Workbook

Sheet 01_概要
B2: Data Cloud コンサルタント
C3: Salesforce.Data-Cloud-Consultant-JPN.v2025-03-28.q66 | D3: =COUNTIFS('02_問題'!$J$4:$J$228,'01_概要'!$C3) -> 66
C4: Salesforce.Data-Cloud-Consultant-JPN.v2024-09-12.q66 | D4: =COUNTIFS('02_問題'!$J$4:$J$228,'01_概要'!$C4) -> 66
C5: Salesforce.Data-Cloud-Consultant.v2024-12-02.q93 | D5: =COUNTIFS('02_問題'!$J$4:$J$228,'01_概要'!$C5) -> 93
C6: 総計 | D6: =SUM(D3:D5) -> 225
B8: 分類 | F8: ◯ | G8: ×
C9: 01_Data Cloud の概要 | D9: =COUNTIFS('02_問題'!$D$4:$D$228,'01_概要'!$C9) -> 29 | E9: =D9/$D$15 -> 0.12888889 | F9: =COUNTIFS('02_問題'!$D$4:$D$228,'01_概要'!$C9,'02_問題'!$C$4:$C$228,'01_概要'!F$8)/$D9 -> 0.96551724 | G9: =COUNTIFS('02_問題'!$D$4:$D$228,'01_概要'!$C9,'02_問題'!$C$4:$C$228,'01_概要'!G$8)/$D9 -> 0.034482759 | H9: 0.18 | I9: =F9*H9 -> 0.1737931
C10: 02_Data Cloud の設定と管理 | D10: =COUNTIFS('02_問題'!$D$4:$D$228,'01_概要'!$C10) -> 34 | E10: =D10/$D$15 -> 0.15111111 | F10: =COUNTIFS('02_問題'!$D$4:$D$228,'01_概要'!$C10,'02_問題'!$C$4:$C$228,'01_概要'!F$8)/$D10 -> 0.94117647 | G10: =COUNTIFS('02_問題'!$D$4:$D$228,'01_概要'!$C10,'02_問題'!$C$4:$C$228,'01_概要'!G$8)/$D10 -> 0.058823529 | H10: 0.12 | I10: =F10*H10 -> 0.11294118
C11: 03_データ取得とデータモデリング | D11: =COUNTIFS('02_問題'!$D$4:$D$228,'01_概要'!$C11) -> 45 | E11: =D11/$D$15 -> 0.2 | F11: =COUNTIFS('02_問題'!$D$4:$D$228,'01_概要'!$C11,'02_問題'!$C$4:$C$228,'01_概要'!F$8)/$D11 -> 0.97777778 | G11: =COUNTIFS('02_問題'!$D$4:$D$228,'01_概要'!$C11,'02_問題'!$C$4:$C$228,'01_概要'!G$8)/$D11 -> 0.022222222 | H11: 0.2 | I11: =F11*H11 -> 0.19555556
C12: 04_ID 解決 | D12: =COUNTIFS('02_問題'!$D$4:$D$228,'01_概要'!$C12) -> 36 | E12: =D12/$D$15 -> 0.16 | F12: =COUNTIFS('02_問題'!$D$4:$D$228,'01_概要'!$C12,'02_問題'!$C$4:$C$228,'01_概要'!F$8)/$D12 -> 0.97222222 | G12: =COUNTIFS('02_問題'!$D$4:$D$228,'01_概要'!$C12,'02_問題'!$C$4:$C$228,'01_概要'!G$8)/$D12 -> 0.027777778 | H12: 0.14 | I12: =F12*H12 -> 0.13611111
C13: 05_セグメンテーションとインサイト | D13: =COUNTIFS('02_問題'!$D$4:$D$228,'01_概要'!$C13) -> 39 | E13: =D13/$D$15 -> 0.17333333 | F13: =COUNTIFS('02_問題'!$D$4:$D$228,'01_概要'!$C13,'02_問題'!$C$4:$C$228,'01_概要'!F$8)/$D13 -> 0.84615385 | G13: =COUNTIFS('02_問題'!$D$4:$D$228,'01_概要'!$C13,'02_問題'!$C$4:$C$228,'01_概要'!G$8)/$D13 -> 0.15384615 | H13: 0.18 | I13: =F13*H13 -> 0.15230769
C14: 06_データの操作 | D14: =COUNTIFS('02_問題'!$D$4:$D$228,'01_概要'!$C14) -> 42 | E14: =D14/$D$15 -> 0.18666667 | F14: =COUNTIFS('02_問題'!$D$4:$D$228,'01_概要'!$C14,'02_問題'!$C$4:$C$228,'01_概要'!F$8)/$D14 -> 0.92857143 | G14: =COUNTIFS('02_問題'!$D$4:$D$228,'01_概要'!$C14,'02_問題'!$C$4:$C$228,'01_概要'!G$8)/$D14 -> 0.047619048 | H14: 0.18 | I14: =F14*H14 -> 0.16714286
C15: 総計 | D15: =SUM(D9:D14) -> 225 | E15: =D15/$D$15 -> 1 | F15: =SUMPRODUCT(F9:F14,$D$9:$D$14)/SUM($D$9:$D$14) -> 0.93777778 | G15: =SUMPRODUCT(G9:G14,$D$9:$D$14)/SUM($D$9:$D$14) -> 0.057777778 | H15: =SUM(H9:H14) -> 1 | I15: =SUM(I9:I14) -> 0.9378515
D21: 0.18 | E21: 0.8 | F21: =D21*E21*100 -> 14.4
D22: 0.12 | E22: 0.75 | F22: =D22*E22*100 -> 9
D23: 0.2 | E23: 0.75 | F23: =D23*E23*100 -> 15
D24: 0.14 | E24: 1 | F24: =D24*E24*100 -> 14
D25: 0.18 | E25: 0.63 | F25: =D25*E25*100 -> 11.34
D26: 0.18 | E26: 0.72 | F26: =D26*E26*100 -> 12.96
F27: =SUM(F21:F26) -> 76.7

Sheet 02_問題
M1: *
B2: JPN | H2: GenAI | M2: *
B3: # | C3: 正誤 | D3: 分類 | E3: 問題 | F3: 解答 | G3: 解説 | H3: 解答 | I3: 解説 | J3: 出所 | K3: 重複# | M3: *
B4: 6 | C4: ◯ | D4: 01_Data Cloud の概要 | E4: Data Cloud で対処できる一般的なユースケースはどれですか? 2つの回答を選択してください A. 顧客データを理解し、それに基づいて行動することで、より関連性の高いエクスペリエンスを実現します。 B. 一元化された一連のポリシーとプロセスを通じて、エンタープライズ データのライフサイクルを管理します。 C. 標準化され拡張可能なデータ モデルを使用して、複数のソースからのデータを調和させます。 D. バックアップと災害対策のための集中システムとして機能し、重要なビジネスデータを保護します。 | F4: A, C | G4: 回復。 説明： Data Cloudは、Salesforceおよび外部ソースを含む多様なデータソースからデータを接続、準備、統合、一元化、クエリ、分析、活用するためのデータプラットフォームです。Data Cloudで対応可能な一般的なユースケースには以下のものが含まれます： 顧客データを理解し、より関連性の高い体験を促進する。Data Cloudは、異なるソースからのデータを統合し、チャネル横断でのアイデンティティを解決することで、顧客の360度ビューを獲得するのを支援します。Data Cloudはまた、顧客セグメンテーション、パーソナライズド体験の創出、インサイトとAIを活用したデータ活用を、あらゆるチャネルで実現するのを支援します。 複数のソースからのデータを標準化され拡張可能なデータモデルで統合する。Data Cloudは、データを活用する前に変換・クリーニングし、拡張・カスタマイズ可能な共通データモデルにマッピングするのを支援します。Data Cloudは、データエンリッチメントやアイデンティティ解決の最適化のため、計算済みインサイトや関連属性を生成する機能も提供します。 他の2つのオプションは、Data Cloudの一般的な使用ケースではありません。Data Cloudはデータガバナンスやバックアップ/災害復旧機能を提供しません。これらの機能は通常、Salesforceの他のソリューションまたは外部ソリューションで処理されます。 参照： Data Cloudの動作原理を学ぶ Salesforce Data Cloudについて プラットフォームのユースケースを発見 一般的なデータ分析のユースケースを理解する | H4: A, C | I4: ◾ 背景：Salesforce Data Cloud の主な役割とは？ Salesforce Data Cloud（旧 CDP）は、主に以下の目的で使用されます： 顧客中心のデータ統合と理解 セグメンテーション、インサイト生成、アクティベーションによるマーケティング最適化 リアルタイムのデータストリームとパーソナライズ体験の実現 つまり、「誰が顧客なのかを理解し、適切なチャネルで、適切なタイミングで、適切な体験を届ける」という一連のサイクルを支えるためのデータプラットフォームです。 ✅ 正解理由： ▶ A. 顧客データを理解し、それに基づいて行動することで、より関連性の高いエクスペリエンスを実現 Data Cloud の 最大の価値は、リアルタイム顧客理解に基づいたアクション（施策） にあります。 Identity Resolution や Streaming Insights、Calculated Insights を通じて、 パーソナライズされたキャンペーンや提案を実現できます。 ▶ C. 標準化され拡張可能なデータモデルを使用して、複数のソースからのデータを調和 Data Cloud は Salesforce CDM（Cloud Data Model）という 拡張可能な標準モデルを用いて、 異なるスキーマ（CRM、EC、アプリ等）からのデータを Harmonization（調和） します。 統一されたデータモデルにより、正確な統合プロファイルの生成と柔軟なセグメント設計が可能になります。 ❌ 誤りの選択肢と理由： 選択肢 理由 B. 一元化されたポリシーとプロセスを通じたエンタープライズデータ管理 ❌ これはMDM（マスターデータ管理）やガバナンスツールの役割。Data Cloud の主目的ではない。 D. バックアップと災害対策のための集中システム ❌ Data Cloud はマーケティング・顧客体験向けの分析/アクティベーション基盤であり、DR（災害対策）用途ではない。 📝 まとめ表： ユースケース内容 Data Cloud として正しいか ✅ 顧客データの理解とアクション ✔️ 正解 ❌ エンタープライズ全体のデータライフサイクル管理 ❌ 不正解（MDM寄り） ✅ 異種データソースの統合と標準化モデルでの調和 ✔️ 正解 ❌ バックアップ/災害対策としての運用 ❌ 不正解（別カテゴリ） | J4: Salesforce.Data-Cloud-Consultant-JPN.v2025-03-28.q66 | K4: - | M4: *
B5: 16 | C5: ◯ | D5: 01_Data Cloud の概要 | E5: データクラウドにおける人工知能 (AI) の役割は何ですか? A. データ検証の自動化 B. 動的なデータ駆動型管理ダッシュボードの作成 C. 洞察と予測を通じて顧客とのやり取りを強化 D. ユースケース用のメールテンプレートの生成 | F5: C | G5: * AIの役割：Salesforce Data Cloudにおいて、人工知能（AI）はデータを活用して洞察と予測を生成し、顧客とのインタラクションを向上させる重要な役割を果たしています。 * 洞察と予測： AIアルゴリズム： 機械学習アルゴリズムを活用して、大量の顧客データを分析します。 予測分析： 顧客の行動傾向、好み、潜在的な将来の行動など、予測可能な洞察を提供します。 * 顧客体験の向上： パーソナライゼーション： 顧客のニーズと好みを予測することで、パーソナライズされた体験を創出します。 効率化： 顧客が連絡を取る前に問題を予測し、解決策を提案することで、プロアクティブなカスタマーサービスを実現します。 マーケティング：ターゲティングとセグメンテーションを最適化し、マーケティング活動を最も有望なリードや顧客に集中させます。 * 活用事例： レコメンドエンジン：過去の行動や好みに基づいて製品やサービスを提案します。 チャーン予測：離反リスクの高い顧客を特定し、リテンション戦略でエンゲージメントを強化します。 * 参照： Salesforce Data Cloud AI機能 Salesforce AI for Customer Interaction | H5: C | I5: ◾ 質問の主旨： Data Cloud（旧 CDP）において、人工知能（AI）の役割とは何か？ Salesforce Data Cloud における AI は、Einstein AI や生成AI（Einstein GPT）と連携して、顧客データから有用な洞察・予測を導き出し、それをパーソナライズされたエクスペリエンスに活かす役割を担っています。 ▶ 正解理由（C）： AIは、Data Cloud に取り込まれた統合顧客データに基づいて： 購入予測 チャーン（離脱）予測 エンゲージメントスコアの推定 セグメントごとのインサイト抽出 リアルタイムでの最適アクションの提案 などを実現することで、顧客体験（CX）の強化に貢献します。 ■ 他の選択肢の検討： 選択肢 評価 理由 A. データ検証の自動化 ❌ 不正解 データの整合性検証やETLは主に データパイプライン・変換ロジックの役割。AIではない B. ダッシュボードの自動作成 ❌ 不正解 ダッシュボードは BIツール（Tableauなど）で作成。AIの直接機能ではない C. 洞察と予測による強化 ✅ 正解 AIの本来の役割そのもの。Einstein予測やセグメントインテリジェンスと連携 D. メールテンプレート生成 ❌ 不正解 これは Einstein GPT for Marketing の役割であり、Data Cloud固有の機能ではない | J5: Salesforce.Data-Cloud-Consultant-JPN.v2025-03-28.q66 | K5: - | M5: *
B6: 45 | C6: ◯ | D6: 01_Data Cloud の概要 | E6: ノーザン トレイル アウトフィッターズはデータ クラウドの実装を希望しており、いくつかのユースケースを念頭に置いています。 Data Cloud に適していると考えられる 2 つのユースケースはどれですか? 2 つの答えを選択してください A. 顧客のアイデンティティを照合するために、さまざまなソースからデータを取り込んで統合するため B. クロスチャネル マーケティング メッセージを作成および調整するため C. 調和されたデータを使用して、顧客とビジネスへの影響をより正確に理解するため D. 個別のビジネス インテリジェンス ツールと IT データ管理ツールの必要性を排除するため | F6: A, C | G6: Data Cloudは、Salesforceおよび外部ソースを含む多様なデータソースからデータを接続、準備、統合、統一、クエリ、分析、活用するためのデータプラットフォームです。Data Cloudが適している主なユースケースは以下の通りです： 多様なソースからデータを収集し統合して顧客のアイデンティティを一致させる。Data Cloudは、ストリーミングデータやバッチデータを含むすべてのデータをSalesforceに統合し、共通のデータモデルにマッピングするのを支援します。Data Cloudは、異なるチャネルやソース間の顧客IDを解決し、統一された顧客プロファイルを作成する支援も可能です。 調和されたデータを活用して、顧客とビジネスへの影響を正確に理解する。Data Cloudは、データを活用する前に変換・クリーニングを行い、計算されたインサイトや関連属性でデータを豊かにする支援が可能です。Data Cloudは、データに基づくセグメントやオーディエンスを作成し、任意のチャネルでアクティベートする支援も可能です。Data Cloudは、AIを活用して顧客の行動や結果を予測する支援も可能です。 他の2つのオプションは、Data Cloudに適したユースケースとは考えられていません。Data Cloudは、クロスチャネルマーケティングメッセージの作成やオーケストレーション機能を提供しません。これは通常、Marketing Cloudなどの他のSalesforceソリューションで処理されます。Data Cloudは、ビジネスインテリジェンスやITデータ管理ツールの必要性を排除するものではありません。これらのツールと連携し、その機能を補完するように設計されています。 参照： Data Cloudの仕組みについて学ぶ Salesforce Data Cloudについて プラットフォームのユースケースを発見する 一般的なデータ分析のユースケースを理解する | H6: A, C | I6: Salesforce Data Cloud は、以下の目的に特化したプラットフォームです： マルチソースの顧客データ統合（ID解決） データの調和と構造化 統一された顧客プロファイルの生成 リアルタイムのセグメンテーションとアクティベーション 顧客行動に基づく分析とインサイト抽出 ✅ 各正解の詳細： ✅ A. 顧客のアイデンティティを照合して統合する Data Cloud の中核機能である ID解決（Identity Resolution） に該当。 顧客が複数チャネルで残した断片的データ（例：メール、電話、Cookie、会員情報など）を1つの「統合プロファイル」にまとめることができる。 ✅ C. 調和されたデータを使ってビジネスインサイトを得る **Harmonization（調和）**されたデータにより、正確で信頼できる顧客像をベースにした分析が可能。 計算されたインサイトやセグメントインテリジェンスを通じて、顧客行動とビジネス成果の関係性を可視化できる。 ❌ 不正解の選択肢： 選択肢 評価 理由 B. クロスチャネル マーケティング メッセージの作成・調整 ❌ 不正解 これは Marketing Cloud（Engagement） の主な領域であり、Data Cloud はセグメント提供や属性補完を担当 D. BI/ITツールの排除 ❌ 不正解 Data Cloud は BIやIT管理の代替ではなく、むしろそれらと連携する補完的存在（TableauやETLツールなどと共存） | J6: Salesforce.Data-Cloud-Consultant-JPN.v2025-03-28.q66 | K6: - | M6: *
B7: 49 | C7: ◯ | D7: 01_Data Cloud の概要 | E7: Data Cloud はどのようにしてデータのプライバシーとセキュリティを確保しますか? A. 保存時および転送中のデータを暗号化することで B. 同意の参照を強制および制御することにより C. オフサイトサーバーにデータを安全に保存することで D. データアクセスを許可された管理者に制限することで | F7: A | G7: * データプライバシーとセキュリティ（データクラウド）： Salesforce Data Cloudにおいて、データプライバシーとセキュリティの確保は最優先事項です。 参照： * 主要なセキュリティ対策： データ暗号化（保管時と転送時）： データ暗号化により、データが保管中および転送中に不正アクセスから保護されます。 同意設定の管理と制御： 同意管理により、データの利用が顧客の許可と規制要件に準拠するように確保されます。 * セキュリティ対策の実施手順： データ暗号化： Salesforce Shieldを使用して、保存中のデータに暗号化を有効化します。 転送中のデータにTLS/SSL暗号化が使用されていることを確認します。 同意管理： Data Cloud内で同意設定を設定し、適用します。 同意記録を定期的に監査し、更新します。 * 実践的な応用： 例： 金融機関は顧客の財務データを暗号化して保護し、GDPRに準拠するために同意管理を実施しています。 | H7: A | I7: Salesforce Data Cloud は、エンタープライズレベルのプラットフォームとして、顧客データのプライバシーとセキュリティを確保するために、複数のセキュリティ対策を実施しています。その中でも最も基本的かつ中核的な対策が： ✅ 「保存時（at rest）」および「転送中（in transit）」のデータ暗号化です。 暗号化の具体例： 保存時：データレイクやデータベースに保存されているデータは AES-256 などの業界標準の方式で暗号化される。 転送中：APIやブラウザ、連携ツールを通じて送信されるデータは TLS/SSL によって暗号化される。 このように、データ漏洩リスクを防止するための根本的な対策が常時適用されています。 ❌ 他の選択肢の誤り： 選択肢 評価 理由 A. 保存時および転送中の暗号化 ✅ 正解 データセキュリティの中核的な技術対策であり、すべての組織に自動で適用される B. 同意の参照を強制および制御する ❌ 一部正しいが不完全 これは 「プライバシー制御の一部（Consent Management）」 にすぎず、暗号化のようなセキュリティの土台ではない C. オフサイトサーバーに保存する ❌ 不正確 どこに保存するかではなく、保存方法（暗号化など）が重要。また「オフサイト」がセキュリティを担保するとは限らない D. 管理者にアクセスを制限する ❌ 不正解 アクセス制御は一部のセキュリティ手段だが、プライバシーとセキュリティの中心対策ではない（しかも「管理者のみ」は過剰制限） | J7: Salesforce.Data-Cloud-Consultant-JPN.v2025-03-28.q66 | K7: - | M7: *
B8: 83 | C8: ◯ | D8: 01_Data Cloud の概要 | E8: Data Cloud はどのようにしてデータのプライバシーとセキュリティを確保しますか? A. 保存時および転送中のデータを暗号化することで B. 同意の参照を強制および制御することにより C. オフサイトサーバーにデータを安全に保存することで D. データアクセスを許可された管理者に制限することで | F8: A | G8: データプライバシーとセキュリティにおけるデータクラウド： * Salesforce Data Cloudにおいて、データプライバシーとセキュリティの確保は最優先事項です。 | H8: A | I8: ◾ 問題の焦点： Salesforce Data Cloud（旧 CDP）は、個人情報（PII）などを含む大量の顧客データを扱うため、データのプライバシーとセキュリティを強固に保護することが必須です。 → この設問では、「Data Cloud が技術的にどのようにしてセキュリティを確保しているか？」を問われています。 ✅ 正解理由：「暗号化（Encryption）」はセキュリティの最前提であり、Data Cloud においても厳格に適用されている ▶ Data Cloud の暗号化戦略： 保存時（At Rest）： データは AES 256ビットなどの暗号方式で暗号化され、物理メディアを含めてセキュアに保管される。 転送中（In Transit）： 通信は常に TLS（SSL） などの暗号化プロトコルを通じて行われ、傍受や改ざんを防止 このように、「保存時」と「転送中」の両方で暗号化を施すことで、包括的なセキュリティ対策が実現されている。 ❌ 他の選択肢の誤り： 選択肢 評価 理由 A. 保存時および転送中の暗号化 ✅ 正解 業界標準かつSalesforce公式で採用されている最も基本的な技術的対策 B. 同意の参照制御 ❌ 一部正しいが限定的 同意管理はプライバシー制御の一部だが、「セキュリティ確保の仕組み」とは異なる C. オフサイトサーバーに保存 ❌ 意味不明・不正確 オフサイト保存だけではセキュリティ対策とは言えず、データ保護の根拠がない D. 管理者にアクセス制限 ❌ 一部正しいが限定的 アクセス制御はセキュリティの一部だが、暗号化のような包括的な技術的対策ではない | J8: Salesforce.Data-Cloud-Consultant-JPN.v2024-09-12.q66 | K8: 49 | M8: *
B9: 127 | C9: ◯ | D9: 01_Data Cloud の概要 | E9: Data Cloud で対処できる 2 つの一般的なユースケースはどれですか? 2 つの答えを選択してください A. 顧客データを理解し、それに基づいて行動し、より関連性の高いエクスペリエンスを推進します。 B. 一元化された一連のポリシーとプロセスを通じて企業データのライフサイクルを管理します。 C. 標準化された拡張可能なデータ モデルを使用して、複数のソースからのデータを調和させます。 D. バックアップと災害復旧のための集中システムとして機能することで、重要なビジネス データを保護します。 | F9: A, C | G9: Data Cloudは、Salesforceおよび外部ソースを含む多様なデータソースからデータを接続、準備、統合、一元化、クエリ、分析、活用できるデータプラットフォームです。Data Cloudで対応可能な主なユースケースは以下の通りです： * 顧客データを理解し、より関連性の高い体験を提供するためのアクションを実行する。Data Cloudは、異なるソースからのデータを統合し、チャネル横断でのアイデンティティを解決することで、顧客の360度ビューを獲得するのを支援します。Data Cloudは、インサイトとAIを活用して顧客セグメンテーション、パーソナライズド体験の創出、あらゆるチャネルでのデータ活用を支援します。 * 複数のソースからのデータを標準化され拡張可能なデータモデルで調和させる。Data Cloudは、データの利用前に変換・クリーニングを行い、拡張・カスタマイズ可能な共通データモデルにマッピングします。また、計算されたインサイトや関連属性を生成し、データエンリッチメントとアイデンティティ解決の最適化を支援します。 他の2つのオプションは、データクラウドの一般的な使用ケースではありません。データクラウドはデータガバナンスやバックアップおよび災害復旧機能を提供しません。これらの機能は通常、Salesforceの他のソリューションまたは外部ソリューションで処理されます。 参考文献： * データクラウドの仕組みについて学ぶ * Salesforceデータクラウドについて * プラットフォームのユースケースを発見する * 一般的なデータ分析のユースケースを理解する | H9: A, C | I9: ◾ Data Cloud の目的と機能： Salesforce Data Cloud は、以下のようなユースケースを支援する **リアルタイムの顧客データプラットフォーム（CDP）**です： 顧客データの統合、標準化、分析、アクション化 リアルタイムでパーソナライズされた体験の提供 複数チャネル・システムにまたがるデータの調和・活用 ✅ 正解理由： 選択肢 解説 A. 顧客データを理解し、それに基づいて行動し、より関連性の高いエクスペリエンスを推進します。 ✅ Data Cloud の中核ユースケース。統合された顧客プロファイルを元に、セグメンテーション・アクティベーション・パーソナライゼーションを実現。 C. 標準化された拡張可能なデータ モデルを使用して、複数のソースからのデータを調和させます。 ✅ Data Cloud の特徴的な機能。データモデル（DMO）とマッピング機能を活用し、CRM・コマース・外部システムからのデータを調和。 ❌ 不正解の選択肢： 選択肢 理由 B. 一元化された一連のポリシーとプロセスを通じて企業データのライフサイクルを管理します。 ❌ これは**データガバナンスやマスター・データ管理（MDM）**の文脈であり、Data Cloud の主目的ではない。 D. バックアップと災害復旧のための集中システムとして機能することで、重要なビジネス データを保護します。 ❌ これはストレージや災害復旧（DR）システムの役割であり、Data Cloud は該当しない。 | J9: Salesforce.Data-Cloud-Consultant-JPN.v2024-09-12.q66 | K9: 6 | M9: *
B10: 137 | C10: ◯ | D10: 01_Data Cloud の概要 | E10: Northern Trail Outfitters は Data Cloud を実装したいと考えており、いくつかのユースケースを念頭に置いています。 Data Cloud に適していると考えられるユースケースはどれですか? 2つの回答を選択してください A. さまざまなソースからデータを取り込んで統合し、顧客のアイデンティティを調整する B. クロスチャネルマーケティングメッセージを作成し、調整する C. 調和されたデータを使用して、顧客とビジネスへの影響をより正確に理解する D. ビジネスインテリジェンスとITデータ管理ツールを別々に用意する必要がなくなる | F10: A, C | G10: Data Cloud は、Salesforce や外部のさまざまなソース間でデータの接続、準備、調整、統合、クエリ、分析、および操作を行うことができるデータ プラットフォームです。Data Cloud に適していると考えられるユース ケースには次のようなものがあります。 * さまざまなソースからデータを取り込んで統合し、顧客 ID を調整します。Data Cloud は、ストリーミングかバッチかを問わず、すべてのデータを Salesforce に取り込み、共通のデータ モデルにマッピングするのに役立ちます。また、Data Cloud は、さまざまなチャネルやソース間で ID を解決し、顧客の統合プロファイルを作成するのにも役立ちます。 * 調和されたデータを使用して、顧客とビジネスへの影響をより正確に把握します。Data Cloud は、お客様がデータを使用する前に変換およびクレンジングし、計算された洞察と関連属性でデータを充実させるのに役立ちます。また、Data Cloud は、お客様がデータに基づいてセグメントとオーディエンスを作成し、任意のチャネルでアクティブ化できるようにも支援します。Data Cloud は、お客様が AI を使用して顧客の行動と結果を予測できるようにも支援します。 他の 2 つのオプションは、Data Cloud に適したユースケースとは見なされません。Data Cloud には、クロスチャネル マーケティング メッセージを作成および調整する機能はありません。これは通常、Marketing Cloud などの他の Salesforce ソリューションによって処理されます。また、Data Cloud は、ビジネス インテリジェンス ツールや IT データ管理ツールと連携して機能を補完するように設計されているため、個別のビジネス インテリジェンス ツールや IT データ管理ツールが不要になるわけではありません。 参考文献: * データクラウドの仕組みを学ぶ * Salesforce Data Cloudについて * プラットフォームのユースケースを見つける * 一般的なデータ分析のユースケースを理解する | H10: A, C | I10: ◾ Data Cloud の目的： Salesforce Data Cloud は、主に以下を目的とした**リアルタイムの顧客データプラットフォーム（CDP）**です： さまざまなデータソースからの取り込みと統合 顧客IDの解決（Identity Resolution） プロファイルの構築と更新 セグメントの作成とアクティベーション 分析・パーソナライズ・予測アクションの実行 ✅ 正解理由の詳細： 選択肢 解説 評価 A. さまざまなソースからデータを取り込んで統合し、顧客のアイデンティティを調整する Data Cloud の主要な機能であり、複数のCRM、Web、店舗、アプリのデータを結合して、1人の顧客を一元化して理解する。 ✅ C. 調和されたデータを使用して、顧客とビジネスへの影響をより正確に理解する 統合された顧客プロファイルを使って、行動・購入傾向・LTVなどのインサイトを導出するのはData Cloudの本質的な価値。 ✅ ❌ 不正解の選択肢： 選択肢 理由 評価 B. クロスチャネルマーケティングメッセージを作成し、調整する メッセージの作成や配信はMarketing Cloudの機能。Data Cloudはそのパーソナライズや対象者特定のためのデータ基盤を担う。 ❌ D. ビジネスインテリジェンスとITデータ管理ツールを別々に用意する必要がなくなる Data Cloud はCDPでありBIツールの代替ではない。BI（例：Tableau）やデータ管理ツールは別に必要。 ❌ | J10: Salesforce.Data-Cloud-Consultant.v2024-12-02.q93 | K10: 45 | M10: *
B11: 187 | C11: ◯ | D11: 01_Data Cloud の概要 | E11: データクラウドの主な目的は何ですか? A. 顧客のゴールデンレコードの提供 B. 販売サイクルと機会の管理 C. マーケティングデータの結果の分析 D. 顧客データの統合と統一 | F11: D | G11: データクラウドの主な目的: * Salesforce Data Cloud の主な機能は、さまざまなソースからの顧客データを統合および統一し、各顧客の単一の包括的なビューを作成することです。 | H11: D | I11: ◾ Data Cloud の主な目的とは？ Salesforce Data Cloud（旧称：CDP = Customer Data Platform）の最大の価値は、 ✅ あらゆるチャネル・システムからの顧客データを統合・標準化し、単一ビュー（Unified Profile）を構築すること ✅ 正解理由： ▶ D. 顧客データの統合と統一 異なるソース（CRM、Web、モバイル、店舗など）からの断片的な顧客データを取り込み、 アイデンティティ解決（Identity Resolution）によって同一人物を認識し、 セグメンテーション、パーソナライズ、インサイト分析に活用できる 統合プロファイル（Unified Customer Profile） を生成。 これは Data Cloud の 中核的な目的です。 ❌ 他の選択肢の誤り： 選択肢 評価 理由 A. ゴールデンレコードの提供 ❌ ゴールデンレコードは MDM（Master Data Management） のコンセプト。Data Cloud は「マーケティング・体験向けの統合プロファイル」を提供するが、業務全体を支えるマスターデータの唯一性保証までは担わない。 B. 販売サイクルと機会の管理 ❌ これは Sales Cloud の役割。Data Cloud は営業活動の直接管理には使われない。 C. マーケティングデータの結果の分析 ❌ Data Cloud は 顧客データ基盤であり、分析は目的の一部だが主目的ではない。 | J11: Salesforce.Data-Cloud-Consultant.v2024-12-02.q93 | K11: - | M11: *
B12: 42 | C12: ◯ | D12: 01_Data Cloud の概要 | E12: 世界的なファッション小売業者は、AMFR、FMFA、APAC 全体でオンライン販売プラットフォームを運営しています。顧客、注文、製品情報のデータ形式は地域によって異なり、コンプライアンス規制では、元のデータ ソースでデータを変更せずに維持することが求められています。また、リアルタイムのパーソナライゼーションと分析のために、顧客プロファイルの統一されたビューも必要です。 これらの要件を考慮すると、企業は受信データ ストリームを標準化およびクレンジングするためにどのような変換アプローチを実装する必要がありますか? A. ストリーミング データ変換を実装します。 B. Data Cloud に取り込む前にデータを変換します。 C. バッチデータ変換を実装します。 D. Apex を使用してデータを変換およびクレンジングします。 | F12: A | G12: A. ストリーミング データ変換を実装します。 ソースによると、ストリーミング データ変換は「ほぼリアルタイムでデータを変換」するものであり、ソース DLO からターゲット DLO へとデータを書き込みます。これは、1 行のデータに対して動作し、ストリーミング プロセスとして継続的に実行され、新しいデータや変更されたデータをピックアップします。要件には「リアルタイムのパーソナライゼーションと分析」が含まれており、ストリーミング変換はリアルタイムまたはほぼリアルタイムの処理に適しています。また、データは Data Cloud に取り込まれて DLO となった後で変換されるため、元のソースデータは変更されずに維持されます。 B. Data Cloud に取り込む前にデータを変換します。 ソースが示す Data Cloud の標準的なデータ取り込みフローは、まずデータを Data Cloud に取り込み (DSO/DLO の作成)、その後データマッピングや変換を行います。Data Cloud に取り込む前にデータを変換することは、ソースデータが変更されてしまう可能性があり、「元のデータソースでデータを変更せずに維持」というコンプライアンス要件と矛盾する可能性があります。また、Data Cloud の価値の一つは、元の DLO を保持しつつ、それを基にさまざまな DMO を作成できる柔軟性にあるとも考えられます。 C. バッチデータ変換を実装します。 ソースによると、バッチデータ変換は「繰り返し可能なプロセス、スケジュールまたは手動でトリガー可能」であり、「フルリフレッシュ」に使用されると説明されています。これはデータ変換の一つの方法ですが、要件で求められている「リアルタイムのパーソナライゼーションと分析」には、バッチ処理よりもストリーミング処理の方が適しています。 D. Apex を使用してデータを変換およびクレンジングします。 ソース では、Apex が ConnectAPI.CDPQuery Apex クラス として、Data Cloud のデータへのアクセスやクエリ実行のために言及されています。しかし、データ ストリームから取り込まれたデータに対して、標準化やクレンジングのためのデータ変換を実行する主要なアプローチとして Apex が示されているわけではありません。Data Cloud には、データ変換のための組み込みツールやプロセスがあります。 これらの点を考慮すると、顧客、注文、製品情報を標準化およびクレンジングし、元のソースデータを変更せずに維持し、かつリアルタイムの要件を満たすためには、Data Cloud にデータを取り込んだ後に、ストリーミング データ変換を実装する というアプローチが、ソースの情報に最も合致していると考えられます。このアプローチにより、地域ごとに異なる形式のデータを Data Cloud 内で標準化された形式に変換し、統一されたプロファイル作成やリアルタイム分析に活用できるようになります。 したがって、ソースに基づいた回答は A. ストリーミング データ変換を実装します。 となります。 正解は A. ストリーミング データ変換を実装します。 | H12: A | I12: ◾ 問題の要点まとめ： グローバルに異なるフォーマットの顧客・注文・製品データを扱っている（AMER, EMEA, APAC） データは 元のソースで変更せずに維持する必要がある（＝元データを直接加工できない） 目的は： リアルタイムパーソナライゼーション 統一された顧客プロファイルビュー 分析対応 よって求められるのは： 🔸 リアルタイム性があり、かつデータをData Cloud内で正規化・整形できる変換処理 ✅ なぜ「A. ストリーミング データ変換」が正解か？ ストリーミングデータ変換とは、Salesforce Data Cloud において： データストリーム取り込み時にリアルタイムで変換・標準化処理を適用できる機能 変換例： 日付フォーマットの統一（MM-DD-YYYY → YYYY-MM-DD） テキストのクレンジング（例："M" → "Male"） 地域ごとの形式差の補正 ▶ 利点： 元データを変更せずに（＝コンプライアンス維持） Data Cloud内部でデータをクリーン・統一・構造化できる リアルタイム分析・パーソナライゼーションにも対応可能 ❌ 他の選択肢の誤り： 選択肢 評価 誤りの理由 B. Data Cloud に取り込む前に変換 ❌ 不正解 「元データを変更せずに維持する」という規制に反する可能性がある C. バッチデータ変換 ❌ 不正解 バッチはリアルタイムではなく、パーソナライゼーションには不向き D. Apex を使った変換 ❌ 不正解 Apex は Data Cloud では使えず、Core Salesforce（CRM）内での処理手段であり不適切 | J12: Salesforce.Data-Cloud-Consultant-JPN.v2025-03-28.q66 | K12: - | M12: *
B13: 107 | C13: ◯ | D13: 01_Data Cloud の概要 | E13: Data Cloud は個人の忘れられる権利をどのように処理しますか? A. すべてのデータ ソース オブジェクトからレコードを削除し、ダウンストリーム データ モデル オブジェクトは次にスケジュールされた取り込み時に更新されます。 B. 指定された個別レコードとその統合個別リンク レコードを削除します。 C. 指定された個人とレコードを、個人データ モデル オブジェクトにマップされたデータ ソース オブジェクトから削除します。 D. 指定された個人と、その個人に関連するデータ モデル オブジェクト/データ レイク オブジェクトからレコードを削除します。 | F13: D | G13: Data Cloudは、個人の「忘れられる権利」を履行するため、指定された個人およびその個人に関連するすべてのデータモデルオブジェクト/データレイクオブジェクトから個人と関連する記録を削除します。これにより、Data Cloudはデータスペースから個人に関連するすべてのデータを削除します。これには、ソースオブジェクトからのデータ、統合された個人プロファイル、および関連するオブジェクトが含まれます。Data Cloudは、個人とソースレコードをリンクする統合個人リンクレコードも削除します。Data Cloudは、忘れられる権利の請求を処理するためにConsent APIを使用し、完全な削除を保証するために30日、60日、90日後に再処理されます。 他のオプションは、Data Cloudが個人の忘れられる権利を処理する方法の正しい説明ではありません。Data Cloudは、すべてのデータソースオブジェクトからレコードを削除しません。これは、ソースシステムのデータ整合性と可用性に影響を与えるためです。Data Cloudはまた、指定された個人レコードとその統一個人リンクレコードのみを削除しません。これは、ソースレコードと関連レコードがそのまま残るためです。Data Cloudは、個人データモデルオブジェクトにマッピングされたデータソースオブジェクトから指定された個人とレコードのみを削除しません。これは、関連レコードがそのまま残るためです。 参照： * データ削除または忘れられる権利の請求 * Data Cloudでのデータ削除 * Data CloudでConsent APIを使用する * Data Cloudにおけるデータとアイデンティティ | H13: D | I13: ◾ 忘れられる権利（Right to Be Forgotten）とは？ GDPRなどのプライバシー規制に基づき、個人は自身のデータを削除するよう組織に求めることができます。 Salesforce Data Cloud では、**「同意管理（Consent Management）」および「削除リクエスト」**を通じてこれを処理します。 ✅ 正解理由： ▶ Data Cloud における削除の仕組み： Data Cloud は「指定された個人（Individual）」と、 その個人に 関連付けられたすべての DMO（データモデルオブジェクト）や DLO（データレイクオブジェクト） からレコードを削除します。 これは以下を含みます： 統合プロファイル（Unified Individual） 個人に関連付けられた購入履歴、エンゲージメントデータなどの DLO/DMO情報 ❌ 他の選択肢の誤り： 選択肢 評価 誤りの理由 A. データソースオブジェクトのみ削除 ❌ データソースオブジェクトは外部連携の取り込み元。削除範囲が不十分 B. Individual と統合リンクのみ削除 ❌ リンクだけでなく、関連データ（注文・接点など）も削除が必要 C. Individual とそのソースデータだけ削除 ❌ 同様に、DMO/DLO からの削除も必要であり、範囲が限定的すぎる D. Individual + 関連DMO/DLOを削除 ✅ 正しいスコープと仕組みを説明している | J13: Salesforce.Data-Cloud-Consultant-JPN.v2024-09-12.q66 | K13: - | M13: *
B14: 210 | C14: ◯ | D14: 01_Data Cloud の概要 | E14: Data Cloud は個人の忘れられる権利をどのように扱いますか? A. すべてのデータソースオブジェクトからレコードを削除し、下流のデータモデルオブジェクトは次回のスケジュールされた取り込み時に更新されます。 B. 指定された個別レコードとその統合個別リンクレコードを削除します。 C. 指定された個人と、個人データ モデル オブジェクトにマップされたすべてのデータ ソース オブジェクトからのレコードを削除します。 D. 指定された個人と、その個人に関連するすべてのデータ モデル オブジェクト/データ レイク オブジェクトからレコードを削除します。 | F14: D | G14: Data Cloud は、指定された個人と、個人に関連するすべてのデータ モデル オブジェクト/データ レイク オブジェクトからレコードを削除することで、個人の忘れられる権利を処理します。つまり、Data Cloud は、ソース オブジェクト、統合された個人プロファイル、および関連オブジェクトのデータを含む、個人に関連付けられたすべてのデータをデータ スペースから削除します。Data Cloud は、個人をソース レコードにリンクする統合された個人リンク レコードも削除します。Data Cloud は、Consent API を使用して忘れられる権利のリクエストを処理します。このリクエストは、完全な削除を確実にするために 30 日、60 日、90 日で再処理されます。 その他のオプションは、Data Cloud が個人の忘れられる権利をどのように処理するかについて正しく説明していません。Data Cloud は、ソース システムのデータの整合性と可用性に影響するため、すべてのデータ ソース オブジェクトからレコードを削除することはありません。また、Data Cloud は、指定された個人レコードとその統合個人リンク レコードのみを削除することもありません。そうすると、ソース レコードと関連レコードがそのまま残るからです。また、Data Cloud は、指定された個人と、個人データ モデル オブジェクトにマップされたデータ ソース オブジェクトからのレコードのみを削除することもありません。そうすると、関連レコードがそのまま残るからです。 参考文献: * データ削除または忘れられる権利の要求 * データクラウドのデータ削除 * Data CloudでConsent APIを使用する * データクラウドにおけるデータとアイデンティティ | H14: D | I14: ◾ 背景： Salesforce Data Cloud は、GDPR（General Data Protection Regulation） や CCPA などのデータプライバシー規制に対応するため、 顧客からの 「忘れられる権利（Right to be Forgotten）」 に基づく削除リクエストを受け付け、個人の全データを削除する機能を提供しています。 ✅ 正解理由： ▶ 「忘れられる権利」の対応とは： 指定された**個人（Individual）**に関連付けられたすべてのデータ（例：行動履歴・トランザクション・プロフィールなど）を削除。 削除対象は、Data Model Object（DMO） や Data Lake Object（DLO） など、 Data Cloud 内のあらゆるデータ構造に渡る。 これはData Subject Rights（DSR）ツールまたはAPIから実行可能で、 一度実行されると、セグメントやアクティベーションにもその個人は含まれなくなる。 ❌ 他の選択肢の誤り： 選択肢 評価 理由 A. データソースオブジェクトのみ削除 ❌ ソースのみ削除しても、Data Cloud 内のモデル／統合データにコピーが残り続ける。完全削除ではない。 B. 統合リンクレコードの削除のみ ❌ 統合リンク（Identity解決のリンク）を削除しても、個人データ自体が削除されるわけではない。 C. 個人と個人DMOのみ削除 ❌ 個人の「行動データ」や「購買履歴」など、DMOやDLOにまたがるデータは削除対象外となり不完全。 📝 補足： 対応手段 説明 DSRツール UIから個人指定で削除リクエストが可能 API（Data Subject API） 外部システムからプログラム的にリクエスト送信 削除範囲 Individual、Event、Purchase、Engagement 等すべての関連レコード | J14: Salesforce.Data-Cloud-Consultant.v2024-12-02.q93 | K14: 107 | M14: *
B15: 39 | C15: ◯ | D15: 01_Data Cloud の概要 | E15: ノーザン トレイル クットフィッターズは、各顧客の生涯価値 (LTV) を計算できるだけでなく、ウェブサイト、モバイル アプリ、および小売チャネルから得られる収益の内訳も作成できるようにしたいと考えています。 Data Cloud でこのユースケースに対処するためにコンサルタントは何を使用する必要がありますか? A. フロー オーケストレーション B. ネストされたセグメント C. メトリック上のメトリック D. ストリーミング データ変換 | F15: C | G15: メトリクス上のメトリクスは、既存のメトリクスを基に新しいメトリクスを作成し、それらに数学的な演算を適用する機能です。この機能は、LTV、ROI、コンバージョン率などの複雑なビジネスメトリクスの計算に役立ちます。例えば、コンサルタントはメトリクス上のメトリクスを使用して、各顧客のLTVを、彼らが異なるチャネルで生成した収益を合計することで計算できます。また、メトリクスの定義でチャネル属性を次元として使用することで、チャネル別の収益の内訳を作成することも可能です。参照： メトリクス上のメトリクス、メトリクス上のメトリクスの作成 | H15: C | I15: ◾ 問題の要点： Northern Trail Outfitters は、次の2つの要素を Data Cloud 上で実現したい： 顧客ごとの LTV（生涯価値） の計算 Web、アプリ、店舗など複数チャネルからの収益内訳の可視化 この要件には、複数のチャネルから得られる収益情報を組み合わせて分析する能力が必要です。 ✅ 正解理由：「メトリック上のメトリック（Metrics on Metrics）」とは？ これは Calculated Insights（CI） の高度な活用法の一種で、 1つの集計（メトリック）をベースに、さらに新たな集計を作成できる機能です。 たとえば： 各チャネル別に計算した売上（Web、アプリ、店舗）を基に、 顧客ごとの 合計LTV を計算したり チャネル別比率を求めたりできる これにより、LTVの構成要素を明確に分解して可視化・分析することが可能になります。 ❌ 他の選択肢の誤り： 選択肢 評価 理由 A. フロー オーケストレーション ❌ 不正解 フローはプロセス自動化ツールであり、LTVや収益分析には使わない B. ネストされたセグメント ❌ 不正解 セグメントの条件を入れ子にする構造。LTV計算などの数値集計には不向き C. メトリック上のメトリック ✅ 正解 複数の収益メトリックを組み合わせてLTVを算出できる唯一の正解 D. ストリーミングデータ変換 ❌ 不正解 データの取り込み変換に関する処理であり、集計や可視化には関係しない | J15: Salesforce.Data-Cloud-Consultant-JPN.v2025-03-28.q66 | K15: - | M15: *
B16: 153 | C16: ◯ | D16: 01_Data Cloud の概要 | E16: Northern Trail Qutfitters は、各顧客の生涯価値 (LTV) を計算できるだけでなく、Web サイト、モバイル アプリ、小売チャネルから得られる収益の内訳も作成したいと考えています。 コンサルタントは、Data Cloud でこのユースケースに対処するために何を使用すればよいでしょうか? A. フローオーケストレーション B. ネストされたセグメント C. メトリクス上のメトリクス D. ストリーミングデータ変換 | F16: C | G16: メトリクス オン メトリクスは、既存のメトリクスに基づいて新しいメトリクスを作成し、それらに数学的演算を適用できる機能です。これは、LTV、ROI、コンバージョン率などの複雑なビジネス メトリクスを計算するのに役立ちます。この場合、コンサルタントはメトリクス オン メトリクスを使用して、さまざまなチャネルで顧客が生み出した収益を合計することで、各顧客の LTV を計算できます。コンサルタントは、チャネル属性をメトリクス定義のディメンションとして使用して、チャネル別の収益の内訳を作成することもできます。参照: メトリクス オン メトリクス、メトリクス オン メトリクスの作成 | H16: C | I16: Northern Trail Outfitters は次の2つの要件を持っています： 各顧客の 生涯価値（LTV: Lifetime Value） を算出したい その LTV を チャネル別（Webサイト／モバイルアプリ／店舗）に内訳したい これは、顧客単位の売上をチャネル別に集計・分析するという、高度な集約ロジックの構築を意味します。 ✅ 正解理由： ▶ C. メトリクス上のメトリクス（Metrics on Metrics） Salesforce Data Cloud の **「計算された洞察（Calculated Insights）」**では、集約済みの指標をさらに集計する機能として「メトリクス上のメトリクス（Metrics on Metrics）」が提供されています。 これにより以下が可能になります： 各チャネルごとの購入金額を個人単位で集計 それらを加算して LTV を算出 LTV の中でチャネル別の構成比を分析（＝内訳） ❌ 他の選択肢の誤り： 選択肢 評価 理由 A. フローオーケストレーション ❌ ワークフローの順次処理の制御ツールであり、数値集計や洞察分析には不向き。 B. ネストされたセグメント ❌ セグメント同士の条件ネストは可能だが、数値計算やチャネル別内訳分析はできない。 D. ストリーミングデータ変換 ❌ データのリアルタイム整形・変換に使うが、LTVや内訳のような履歴集計・分析には不適。 | J16: Salesforce.Data-Cloud-Consultant.v2024-12-02.q93 | K16: 39 | M16: *
B17: 2 | C17: ◯ | D17: 01_Data Cloud の概要 | E17: 組織は、ユーザーがオプションの選択リストからテキスト属性を識別して選択できるようにしたいと考えています。 このユースケースではどのデータ クラウド機能が役立つでしょうか? A. 値の提案 B. データの調和 C. 変換式 D. グローバル選択リスト | F17: A | G17: 値提案は、データクラウドの機能で、セグメントフィルターを作成する際、テキストフィールドの可能な値を表示し選択できる機能です。値提案は、DMOレコードのホーム画面で、各データモデルオブジェクト（DMO）フィールドに対して有効または無効に設定できます。値提案は、ユーザーがオプションのリストからテキスト属性を選択する際、正確な値を入力したり記憶したりする必要なく、値を特定して選択するのに役立ちます。また、セグメントフィルターに一貫性があり有効な値を保証することで、エラーを削減しデータ品質を向上させます。参照： セグメンテーションでの値提案の使用、関連属性の選択に関する考慮事項 | H17: A | I17: ◾ 問題文の要点： 組織は、ユーザーがオプションの選択リストからテキスト属性を識別して選択できるようにしたい。 これは、ユーザーが入力する際に候補値が提示されることで、 入力ミスを防ぎ 一貫した属性値を使い 効率的に作業ができるようにする といったユースケースです。 値の提案（Suggested Values） Data Cloudの属性フィールドに対して、既存データに基づいた代表的な値（候補値）を自動提示する機能。選択肢から選べるようにするというユースケースにマッチ。 「値の提案」機能は、Data Cloudでテキスト属性フィールドに対して動的に推奨値を提示できる唯一の選択肢です。 この機能により、マーケターやオペレーターが過去の傾向に基づいた一貫した入力を行えるようになります。 | J17: Salesforce.Data-Cloud-Consultant-JPN.v2025-03-28.q66 | K17: - | M17: *
B18: 22 | C18: ◯ | D18: 01_Data Cloud の概要 | E18: Salesforce Data Cloud の典型的な使用例は何ですか? A. Salesforce エコシステム全体でのデータ同期 B. パーソナライズされたメールを大規模に送信する C. CRMデータをPromiseに保存する D. 複数のプラットフォーム間でのデータの調和 | F18: D | G18: - | H18: D | I18: ◾ Salesforce Data Cloud（旧 CDP）の主な目的： Salesforce Data Cloud は、複数のデータソースからの顧客データをリアルタイムで統合・標準化（調和）し、1つの統合顧客プロファイル（Unified Profile）を作成するためのプラットフォームです。 その中心的な機能は以下の通り： データ調和（Harmonization）：複数のCRM、EC、POS、アナリティクスなどからのデータを共通モデルに整形 ID解決（Identity Resolution）：顧客の断片的な情報を1人の個人として統合 リアルタイムセグメンテーション：マーケティングや営業で即座に活用 パーソナライゼーションやアクティベーション：広告やメール配信、提案などに連携 ■ 各選択肢の評価： 選択肢 評価 理由 A. Salesforce エコシステム全体でのデータ同期 ❌ 不正解 Data Cloud は統合・分析に特化しており、同期エンジン（例：Salesforce Connect、MuleSoft）ではない B. パーソナライズされたメールの送信 ❌ 部分的には関連 実際に送信するのは Marketing Cloud。Data Cloud はセグメントや属性の提供元 C. CRMデータをPromiseに保存 ❌ 不正解 "Promise" という保存領域は存在しない。無関係な表現 D. 複数プラットフォーム間のデータの調和 ✅ 正解 まさに Data Cloudの中心機能。「Harmonization」とも呼ばれる | J18: Salesforce.Data-Cloud-Consultant-JPN.v2025-03-28.q66 | K18: - | M18: *
B19: 46 | C19: ◯ | D19: 01_Data Cloud の概要 | E19: ノーザン トレイル アウトフィッターズは、Marketing Cloud データの一部を Data Cloud で使用したいと考えています。 どのエンゲージメント チャネル データにカスタム統合が必要ですか? A. SMS B. 電子メール C. クラウドページ D. モバイルプッシュ | F19: C | G19: CloudPageは、Marketing Cloudでホストされ、カスタマイズ可能なウェブページです。これは、Data Cloudが標準でサポートするエンゲージメントチャネルの一つではありません。Data CloudでCloudPageのデータを使用するには、カスタム統合が必要です。その他のエンゲージメントチャネル（SMS、メール、モバイルプッシュ）はData Cloudでサポートされており、Marketing Cloud ConnectorまたはMarketing Cloud APIを使用して統合できます。参照：Data Cloudの概要、Marketing Cloud Connector、Marketing Cloud API | H19: C | I19: ◾ 問題の背景： ノーザン トレイル アウトフィッターズは、Marketing Cloud にあるエンゲージメントチャネルのデータを Salesforce Data Cloud で活用したい。 そのうち「どのチャネルのデータにはカスタム統合が必要か？」を問う問題です。 ✅ 正解理由：「CloudPages」データにはカスタム統合が必要 ▶ CloudPagesとは： Marketing Cloud の ランディングページ作成・ホスト機能 主に Webフォーム、キャンペーンページ、アンケートなどのデジタル体験提供に使われる ▶ なぜカスタム統合が必要か？ CloudPages の利用データ（閲覧履歴、フォーム入力など）は標準では Data Cloud に取り込まれない そのため、CloudPagesのログやインタラクションデータを 個別に ETL処理や API連携で Data Cloud に取り込む必要がある Salesforce が提供する 標準のMC連携（Connect）ではサポートされていない ❌ 他の選択肢の誤り： 選択肢 評価 理由 A. SMS ❌ 不正解 SMS送信データは 標準のMarketing Cloud連携で自動連携可能 B. 電子メール ❌ 不正解 電子メールのオープン・クリック・バウンス等は Marketing Cloud連携で自動でData Cloudへ送信可能 C. クラウドページ ✅ 正解 唯一、標準連携では連携されないエンゲージメントチャネル。 カスタム統合が必要 D. モバイルプッシュ ❌ 不正解 モバイルプッシュのインタラクションデータも Marketing Cloudとの連携で取得可能（MobilePushとData Cloudは接続可） | J19: Salesforce.Data-Cloud-Consultant-JPN.v2025-03-28.q66 | K19: - | M19: *
B20: 73 | C20: ◯ | D20: 01_Data Cloud の概要 | E20: 顧客にとってのデータクラウドの主な価値は何ですか? A. 顧客とその関連データの統合ビューを提供するため B. すべてのシステムをゴールデン レコードで接続するには C. すべての匿名データに対する単一の信頼できる情報源を作成するには D. 顧客の行動を聞き、理解し、それに基づいて行動することで、パーソナライズされたキャンペーンを作成するため | F20: A | G20: Data Cloudは、Salesforceアプリケーションおよび他のシステム全体で顧客データを有効活用できるプラットフォームです。Data Cloudは、CRM、マーケティング、コマース、サービス、外部データプロバイダーなど、多様なソースからデータを収集、変換、連携することで、各顧客の統一されたプロファイルを作成できます。また、顧客の行動、好み、ニーズに関する洞察と分析を提供し、顧客セグメンテーション、ターゲティング、パーソナライズされた顧客インタラクションを実現するためのツールも備えています。Data Cloudの顧客への主な価値は、顧客とその関連データを統一されたビューで提供することです。これにより、より良い顧客体験の提供、ロイヤルティの向上、成長の促進が可能になります。参照：Salesforce Data Cloud、データが競争優位性を生むとき | H20: A | I20: Data Cloudが顧客にとって提供する主な価値についてのご質問ですね。ソース資料に基づき、この価値を最もよく表している選択肢とその理由をご説明します。 提示された選択肢は以下の通りです。 A. 顧客とその関連データの統合ビューを提供するため B. すべてのシステムをゴールデン レコードで接続するには C. すべての匿名データに対する単一の信頼できる情報源を作成するには D. 顧客の行動を聞き、理解し、それに基づいて行動することで、パーソナライズされたキャンペーンを作成するため ソース資料によると、Data Cloudの主要な目的と価値は、顧客データを統合して単一のビューを作成し、それに基づいて顧客をより深く理解し、リアルタイムデータなどを用いて行動を起こし、パーソナライズされた顧客体験を創出することにあります | J20: Salesforce.Data-Cloud-Consultant-JPN.v2024-09-12.q66 | K20: - | M20: *
B21: 79 | C21: × | D21: 01_Data Cloud の概要 | E21: 顧客とのプライバシー法に関する議論の際、顧客は忘れられる権利の要求を尊重する必要があると述べました。コンサルタントは、Consent API がこのビジネス ニーズを解決すると判断しました。 コンサルタントが顧客に通知すべき 2 つの考慮事項はどれですか? 2 つの答えを選択してください A. データ削除リクエストは 30、60、90 日後に再処理されます。 B. データ削除リクエストは 1 時間以内に処理されます。 C. データ削除リクエストは個別のプロファイルに対して送信されます。 D. Data Cloud に送信されたデータ削除リクエストは、接続されているすべての Salesforce クラウドに渡されます。 | F21: C, D | G21: SalesforceのConsent APIを使用して「忘れられる権利」の請求に対応する際、顧客にアドバイスする際は、以下の2つの主要な点を重点的に説明する必要があります： * データ削除請求は個人プロファイルに対して提出されます（回答C）：SalesforceのConsent APIは、個人プロファイルに関するデータ削除請求を処理するように設計されています。つまり、データ削除の請求が提出されると、Salesforceシステム内の個人のプロファイルに紐付いた個人データが対象となります。コンサルタントは、正確な処理とプライバシー法への準拠を確保するため、リクエストは個人プロファイルに限定する必要があることを顧客に伝える必要があります。 * Data Cloudに提出されたデータ削除リクエストは、すべての接続されたSalesforceクラウドに伝播されます（回答D）：Salesforce Data CloudのConsent APIを通じてデータ削除リクエストが提出された場合、そのリクエストはData Cloudに限定されません。代わりに、Sales Cloud、Service Cloud、Marketing Cloudなど、接続されたすべてのSalesforceクラウドに伝播されます。これにより、Salesforceエコシステム全体で「忘れられる権利」への包括的な準拠が確保されます。顧客は、削除リクエストが接続されたSalesforce環境内の個人のデータすべてのインスタンスに影響を与えることを認識する必要があります。 | H21: C, D | I21: ◾ 問題の背景： 顧客は「忘れられる権利（Right to be Forgotten）」＝GDPRなどのプライバシー法に準拠したデータ削除リクエストを尊重したいと考えており、 コンサルタントはこのニーズに対して Salesforce Data Cloud の Consent API を使用すべきと判断しました。 ✅ 正解の理由： ▶ B. データ削除リクエストは 1 時間以内に処理されます。 Consent API 経由で送信された削除リクエストは、原則として 1 時間以内に自動処理されるとドキュメントに記載されています。 これにより、ほぼリアルタイムに削除フローが動作することを顧客に説明できます。 ▶ C. データ削除リクエストは個別のプロファイルに対して送信されます。 Consent API は 個人単位（= 個別プロファイル / Individual） に対して使用されます。 リクエストには、対象となる 統合IDや識別情報（例：Email, IDなど） を含める必要があります。 ❌ 他の選択肢の誤り： 選択肢 評価 理由 A. 30、60、90日後に再処理される ❌ 不正確 Data Cloud における削除は 基本的に一度で完結。スケジュールされた再処理はありません。 D. 接続されたすべての Salesforce クラウドに削除される ❌ 誤り Consent API の削除リクエストは Data Cloud 内のデータに限定され、Salesforce CRM や Marketing Cloud などには自動伝播されません。別途対応が必要。 | J21: Salesforce.Data-Cloud-Consultant-JPN.v2024-09-12.q66 | K21: - | M21: *
B22: 81 | C22: ◯ | D22: 01_Data Cloud の概要 | E22: Data Cloud はどのようにして顧客データの高可用性とフォールト トレランスを確保するのでしょうか? A. 複数の地域やデータセンターにデータを分散することで B. 堅牢なバックアップを備えたデータセンターを使用することで C. 自動データ復旧手順を実装することにより D. データへのアクセスを重要な担当者に制限することで | F22: A | G22: 高可用性と障害耐性の確保： * 高可用性とは、システムが継続的に動作し、アクセス可能な状態を維持することを指します。一方、障害耐性とは、障害が発生した場合でも機能を継続する能力を指します。 | H22: A | I22: ◾ 問題の本質： Data Cloud（旧 Customer Data Platform）は、顧客データを常に利用可能に保ちつつ、障害が発生しても迅速に復旧できるよう、**高可用性（HA）とフォールトトレランス（FT）**を保証する設計が必要です。 → このような可用性と耐障害性は、どのように実現されているかを問う問題です。 ✅ 正解理由：「地理的に分散されたデータセンターによる冗長構成」が HA/FT の基本戦略 ▶ Salesforce Data Cloud は： グローバルなマルチリージョン設計を採用しており、 顧客データは 複数の物理リージョン（地域）とデータセンターに分散保存されます。 これにより、1つのデータセンターやリージョンに障害が発生しても： 別のリージョンから継続的にサービス提供が可能（高可用性） データの損失リスクを最小限に抑えられる（フォールトトレランス） ❌ 他の選択肢の誤り： 選択肢 評価 理由 A. 地域・データセンターへの分散 ✅ 正解 クラウドインフラでの標準的な高可用性設計。Salesforceもこの戦略を採用 B. 堅牢なバックアップを使う ❌ 不十分 バックアップは災害復旧の手段であり、リアルタイムの可用性確保には不十分 C. 自動データ復旧手順 ❌ 一部正しいが限定的 復旧は事後対策であり、可用性維持の“予防”にはならない D. アクセス制限 ❌ 無関係 アクセス制御はセキュリティであり、可用性や冗長性とは無関係 | J22: Salesforce.Data-Cloud-Consultant-JPN.v2024-09-12.q66 | K22: - | M22: *
B23: 96 | C23: ◯ | D23: 01_Data Cloud の概要 | E23: Cloud Kicks は、顧客から忘れられるようにというリクエストを受け取りました。 このリクエストに応えるために、コンサルタントはデータ クラウドをどの 2 つの方法で使用する必要がありますか? 2 つの答えを選択してください A. 受信データ ストリームからデータを削除し、完全な更新を実行します。 B. 個別 ID をヘッダーなしファイルに追加し、ファイルから削除機能を使用します。 C. データ エクスプローラーを使用して個人を見つけ、手動で削除します。 D. 同意 API を使用して処理を抑制し、ソース データ ストリームから個人レコードと関連レコードを削除します。 | F23: B, D | G23: 顧客からの「忘れられる権利」の請求に対応するため、コンサルタントはData Cloudを以下の2つの方法で使用する必要があります： * ヘッダーのないファイルに個人IDを追加し、ファイルからの削除機能を使用します。このオプションでは、コンサルタントがCSVファイルにIDを記載してアップロードすることで、Data Cloudから複数の個人データを削除できます1。削除処理は非同期で行われ、完了まで最大24時間かかる場合があります1。 * Consent APIを使用して処理を抑制し、個人および関連レコードをソースデータストリームから削除します。このオプションでは、コンサルタントはConsent APIを使用してData Cloud内の個人プロファイルに対してデータ削除リクエストを送信できます2。データ削除リクエストは、指定された個人エンティティおよびそのエンティティの識別属性と個人ID属性との間で関係が定義されているすべてのエンティティを削除します2。削除プロセスは、完全な削除を保証するために30日、60日、90日に再実行されます2。他のオプションは正しくない理由は： * 入力データストリームからデータを削除し、完全なリフレッシュを実行しても、Data Cloud内の既存データは削除されず、ソースシステムからの新規データのみが削除されます3。 * Data Explorerを使用して個人を特定し手動で削除しても、ソースデータストリーム内の関連レコードは削除されず、Data Cloud内の個人エンティティのみが削除されます。参照： * Data Cloudから個人を削除する * データ削除または忘れられる権利の請求 * Data Cloudのデータリフレッシュ * ［Data Explorer］ | H23: B, D | I23: ◾ 問題の背景： Cloud Kicks は顧客から「忘れられる権利（Right to be Forgotten）」に基づいた削除依頼を受けています。 このようなリクエストに対応するには、Salesforce Data Cloud 上から個人データを適切かつ安全に削除・抑制する必要があります。 ✅ 正解理由と処理方法： ▶ B. ヘッダーなしファイルで削除（ファイルベース削除） Data Cloud では **「ファイルから削除（Delete from File）」**機能を使って、 個別 ID をリスト形式でアップロードし、対象レコードを削除可能。 このとき、ファイルは通常 ヘッダーなし（IDのみのリスト） で作成される。 ▶ D. 同意 API（Consent API）による抑制・削除 Consent API を使えば、**プログラム的にユーザーの「削除」「処理の制限」**を指定できる。 これは 自動化対応や法規制への準拠（例：GDPR） に非常に重要。 ❌ 他の選択肢の誤り： 選択肢 評価 誤りの理由 A. データストリームから削除して完全更新 ❌ ストリームの削除・再作成は 非効率かつ残留リスクがあるため非推奨 C. データエクスプローラーで手動削除 ❌ 一時的な確認には使えるが、GDPRや大量処理には不適・証跡も残らないため不十分 | J23: Salesforce.Data-Cloud-Consultant-JPN.v2024-09-12.q66 | K23: - | M23: *
B24: 100 | C24: ◯ | D24: 01_Data Cloud の概要 | E24: 信頼ベースのファーストパーティ データ資産を構築するとはどういう意味ですか? A. データの使用に同意し、その対価として価値を受け取る個人から収集したデータの透明性とセキュリティを提供するため B. すべてのコンプライアンス規制に従って、信頼できるファーストパーティ データを Data Cloud Marketplace に提供するため C. 法律で義務付けられているすべての電子メール マーケティングに対してオプトイン同意が確実に収集されるようにするため D. インタビュー、調査、世論調査を通じて信頼できる情報源から競合データを入手するため | F24: A | G24: 信頼に基づく第一者データ資産を構築するとは、顧客や見込み客からデータを収集し、管理し、活用する際に、彼らのプライバシーと好みを尊重する方法を意味します。また、データの利用方法、データ共有によるメリット、データ管理の方法について、明確で正直な情報を提供することも含まれます。これにより、顧客との相互に利益となる関係を築くことができます。顧客は、自社のデータを責任を持って倫理的に利用する信頼を寄せ、より関連性が高くパーソナライズされた体験を提供できます。信頼に基づくファーストパーティデータ資産は、顧客の忠誠心、離反防止、成長の向上に加え、データ保護規制や基準への準拠にも役立ちます。参考文献：ファーストパーティデータを活用した強力なデジタル体験、ファーストパーティデータがデータプライバシーの鍵となる理由、ファーストパーティデータ戦略の構築 | H24: A | I24: ◾「信頼ベースのファーストパーティ データ資産」とは？ これは、以下のような 顧客中心のアプローチで構築されたデータ資産 を意味します： 企業が 直接、本人から収集したデータ（ファーストパーティデータ） その収集・利用には、同意（コンセント） が取得されており、 顧客に対して「データ利用の透明性」「価値の提供（パーソナライズ、特典など）」が確保されている つまり、“信頼”に基づいて、顧客と価値を交換しながらデータを取得・利用する形です。 ✅ Salesforce や業界での定義： Salesforce の Data Cloud や CDP のドキュメントでは、 "Building a trusted first-party data asset means collecting consented data transparently, and using it to provide better experiences to your customers." ❌ 他の選択肢の誤り： 選択肢 評価 誤りの理由 A. ✅ 最も正確な定義。透明性、同意、顧客への価値提供を含む B. ❌ Data Cloud Marketplace は データ販売の話であり、「資産構築」ではない C. ❌ メール同意だけに限定しており、文脈が狭すぎる D. ❌ 競合データ（＝サードパーティデータ）であり、ファーストパーティの信頼資産とは無関係 | J24: Salesforce.Data-Cloud-Consultant-JPN.v2024-09-12.q66 | K24: - | M24: *
B25: 102 | C25: ◯ | D25: 01_Data Cloud の概要 | E25: 顧客にとって Data Cloud の主な価値は何ですか? A. すべての匿名データのための唯一の真実のソースを作成する B. 顧客の行動に耳を傾け、理解し、行動することでパーソナライズされたキャンペーンを作成する C. すべてのシステムをゴールデンレコードで接続する D. 顧客と関連データの統合ビューを提供する | F25: D | G25: Data Cloudは、Salesforceアプリケーションおよび他のシステム全体で顧客データを統合し活用できるプラットフォームです。Data Cloudは、CRM、マーケティング、コマース、サービス、外部データプロバイダーなど、多様なソースからデータを収集、変換、連携することで、各顧客の統一されたプロファイルを作成できます。また、顧客の行動、好み、ニーズに関する洞察と分析を提供し、顧客セグメンテーション、ターゲティング、パーソナライズされた顧客インタラクションを実現するためのツールも備えています。Data Cloudの顧客への主な価値は、顧客とその関連データを統合したビューを提供することです。これにより、より良い顧客体験の提供、ロイヤルティの向上、成長の促進が可能になります。参照：Salesforce Data Cloud、データが競争優位性を生み出すとき | H25: D | I25: ◾ 解説： Salesforce Data Cloud の主な価値は、複数のシステムやチャネルから収集された顧客データを統合し、**一貫性のある 360 度の顧客ビュー（統合プロファイル）**を提供することです。 これにより企業は以下を実現できます： 顧客の全体像を把握し マーケティング、営業、サービスで活用し よりパーソナライズされた対応が可能になる ✅ 正解理由：D. 顧客と関連データの統合ビューを提供する Data Cloud は断片化されたデータを統合し、1人の顧客に関するすべての情報（行動・属性・関係性など）をひとつのビューで表示できるようにします。 これが他のクラウドや分析、キャンペーンにおける出発点となる価値です。 ❌ 他の選択肢の誤り： 選択肢 誤りの理由 A. すべての匿名データのための唯一の真実のソースを作成する ❌ Data Cloud は主に識別可能な顧客データを扱います。匿名データ特化ではない。 B. パーソナライズされたキャンペーンを作成する ❌ 確かに重要なユースケースですが、それは「統合ビュー」の次の活用ステップであり、主目的ではありません。 C. ゴールデンレコードで接続する ❌ 「ゴールデンレコード」は MDM（マスターデータ管理）の用語であり、Data Cloud の範疇とは異なります。Data Cloud は最も信頼できる単一ビューを提供しますが、マスターではありません。 📝 まとめ | 主な価値 | ✔️ 顧客と関連データの統合ビューを提供する | | 間接的な価値 | パーソナライズ、キャンペーン強化、レポート改善など | | 主に扱うデータ | 識別可能なファーストパーティデータ（＋エンゲージメント） | | J25: Salesforce.Data-Cloud-Consultant-JPN.v2024-09-12.q66 | K25: 73 | M25: *
B26: 142 | C26: ◯ | D26: 01_Data Cloud の概要 | E26: 信頼に基づくファーストパーティ データ資産を構築するとはどういう意味ですか? A. 使用に同意し、その見返りに価値を受け取る個人から収集したデータの透明性とセキュリティを確保するため B. すべてのコンプライアンス規制に準拠した、信頼できるファーストパーティデータをデータクラウドマーケットプレイスで提供する C. 法律で義務付けられているすべての電子メールマーケティングでオプトインの同意が収集されるようにするため D. インタビュー、アンケート、世論調査を通じて信頼できる情報源から競合データを入手する | F26: A | G26: 信頼に基づくファーストパーティ データ アセットを構築するということは、自社の顧客や見込み客のプライバシーと好みを尊重しながらデータを収集、管理、アクティブ化することを意味します。また、データの使用方法、データ共有によって期待できるメリット、データの管理方法について、明確で正直な情報を顧客に提供することも意味します。そうすることで、顧客と相互に有益な関係を築くことができ、顧客は責任を持って倫理的にデータを使用することを信頼し、より関連性の高いパーソナライズされたエクスペリエンスを顧客に提供できます。信頼に基づくファーストパーティ データ アセットは、顧客ロイヤルティ、維持、成長を向上させるとともに、データ保護の規制や標準に準拠するのに役立ちます。参考資料: 強力なデジタル エクスペリエンスを実現するファーストパーティ データの使用、ファーストパーティ データがデータ プライバシーの鍵となる理由、ファーストパーティ データ戦略の構築 | H26: A | I26: ◾ 背景： 「信頼に基づくファーストパーティ データ資産」とは、企業が顧客から直接収集したデータを、顧客の同意と信頼に基づいて適切に管理・活用することを意味します。 この考え方は、近年の**プライバシー保護の高まり（GDPR, CCPA など）**や、クッキーレス社会への対応として非常に重要視されています。 ✅ 正解理由： ▶ A. 使用に同意し、その見返りに価値を受け取る個人から収集したデータの透明性とセキュリティを確保するため 「ファーストパーティデータ」とは、企業が自社チャネル（Webサイト、アプリ、POSなど）を通じて直接取得したデータです。 「信頼に基づく」とは、ユーザーがその使用に明示的に同意し（例：オプトイン）、見返りとしてサービスや価値を受け取るという、相互信頼のある関係性を指します。 Salesforce などが提唱する信頼ベースのデータ戦略では、この考え方を軸に、透明性・セキュリティ・ガバナンスが強調されています。 ❌ 他の選択肢の誤り： 選択肢 理由 評価 B. データクラウドマーケットプレイスで提供する ❌ 「マーケットプレイスで提供」はセカンド／サードパーティデータの文脈であり、ファーストパーティの信頼構築とは関係が薄い。 C. オプトイン同意の収集 ❌ 一部正しいが、メールマーケティングに限定されすぎており、全体的な信頼に基づく資産構築とは言い切れない。 D. 競合データを入手 ❌ ファーストパーティデータではなく、外部ソースやサードパーティデータの文脈。信頼とは無関係。 | J26: Salesforce.Data-Cloud-Consultant.v2024-12-02.q93 | K26: 100 | M26: *
B27: 158 | C27: ◯ | D27: 01_Data Cloud の概要 | E27: 顧客とのプライバシー法に関する話し合いの中で、顧客は忘れられる権利の要求を尊重する必要があることを示唆しました。コンサルタントは、Consent API がこのビジネス ニーズを解決できると判断しました。 コンサルタントが顧客に伝える必要がある 2 つの考慮事項はどれですか? 2つの回答を選択してください A. データ削除リクエストは 30 日、60 日、90 日後に再処理されます。 B. データ削除リクエストは 1 時間以内に処理されます。 C. 個々のプロファイルに対してデータ削除リクエストが送信されます。 D. Data Cloud に送信されたデータ削除リクエストは、接続されているすべての Salesforce クラウドに渡されます。 | F27: C, D | G27: 忘れられる権利の要求に応じるために Salesforce の Consent API を使用することについて顧客にアドバイスする場合、コンサルタントは次の 2 つの主な考慮事項に重点を置く必要があります。 * データ削除リクエストは、個々のプロファイルに対して送信されます (回答 C): Salesforce の Consent API は、個々のプロファイル専用のデータ削除リクエストを処理するように設計されています。つまり、データ削除リクエストは、Salesforce システム内の個人のプロファイルに関連付けられた個人データを対象とします。コンサルタントは、正確な処理とプライバシー法の遵守を確実にするために、リクエストは個々のプロファイルに固有のものである必要があることを顧客に通知する必要があります。 * Data Cloud に送信されたデータ削除リクエストは、接続されているすべての Salesforce クラウドに渡されます (回答 D): Salesforce Data Cloud の Consent API を通じてデータ削除リクエストが行われた場合、そのリクエストは Data Cloud だけに限定されません。Sales Cloud、Service Cloud、Marketing Cloud など、接続されているすべての Salesforce クラウドに伝播されます。これにより、Salesforce エコシステム全体で忘れられる権利への包括的なコンプライアンスが確保されます。お客様は、削除リクエストが接続されている Salesforce 環境全体の個人データのすべてのインスタンスに影響することを認識しておく必要があります。 | H27: C, D | I27: ◾ 背景： 顧客は「忘れられる権利（Right to be Forgotten）」＝個人データの完全な削除の要求に対応したいと考えています。 Salesforce Data Cloud ではこれに対応するために Consent API（同意・削除リクエスト処理用） が用意されています。 ✅ 正解理由： ▶ B. データ削除リクエストは 1 時間以内に処理されます。 Consent API によるデータ削除リクエストは、Salesforce Data Cloud 側で標準的に約1時間以内に処理されることが保証されています。 これは、プライバシー対応として十分迅速であることを意味し、ユーザーからの正式な「削除要求」に対してタイムリーな対応が可能です。 ▶ C. 個々のプロファイルに対してデータ削除リクエストが送信されます。 削除リクエストは、特定の Individual（個人）プロファイル ID を対象に送信されます。 これにより、その個人に関連するすべてのデータ（属性・接点・イベントなど）が削除対象となります。 ❌ 他の選択肢の誤り： 選択肢 理由 評価 A. 再処理される（30日、60日など） ❌ 一度送信された削除リクエストは再処理されず、単回で処理完了します。定期的な再処理スケジュールは存在しません。 D. すべての Salesforce クラウドに渡される ❌ Consent API は Data Cloud 内部の処理専用であり、Salesforceの他クラウド（Sales、Serviceなど）へ自動的に連携されることはない。別途処理が必要です。 | J27: Salesforce.Data-Cloud-Consultant.v2024-12-02.q93 | K27: 79 | M27: *
B28: 204 | C28: ◯ | D28: 01_Data Cloud の概要 | E28: Northern Trail Outfitters は、Marketing Cloud データの一部を Data Cloud で使用したいと考えています。 どのエンゲージメント チャネル データにカスタム統合が必要ですか? A. SMS B. メール C. クラウドページ D. モバイルプッシュ | F28: C | G28: CloudPage は、Marketing Cloud によってパーソナライズおよびホストできる Web ページです。これは、Data Cloud がすぐにサポートする標準のエンゲージメント チャネルの 1 つではありません。Data Cloud で CloudPage データを使用するには、カスタム統合が必要です。その他のエンゲージメント チャネル (SMS、メール、モバイル プッシュ) は Data Cloud によってサポートされており、Marketing Cloud Connector または Marketing Cloud API を使用して統合できます。参照: Data Cloud の概要、Marketing Cloud Connector、Marketing Cloud API | H28: C | I28: ◾ 背景： Salesforce Marketing Cloud のデータを Salesforce Data Cloud に取り込む際、一部のチャネルは標準で統合対応済みですが、他の一部チャネルはカスタム統合が必要です。 **「クラウドページ（CloudPages）」**はその代表的な例です。 ✅ 正解理由： ▶ クラウドページ（CloudPages）とは？ CloudPages は、Marketing Cloud でホストされるランディングページ／フォーム送信ページ／ウェブビューなど。 顧客がどのページを見たか・どんなフォームを送信したかといった行動ログは、Marketing Cloud Engagement に保存されるが、Data Cloudと標準連携されない。 → よって、CloudPages のエンゲージメントデータを Data Cloudで活用するには、API連携などの カスタム統合が必要となります。 ❌ 他の選択肢の誤り： 選択肢 評価 理由 A. SMS ❌ Marketing CloudのMobile Studio経由で送信されたSMSの配信・開封データは標準でData Cloudと統合可能。 B. メール ❌ Email Studioの送信、開封、クリック等のイベントはData Cloudにネイティブ統合済み。 D. モバイルプッシュ ❌ MobilePushの通知データもData Cloudに標準統合可能。 📝 補足： チャネル Data Cloud 統合方法 メール 標準統合（ネイティブ） SMS 標準統合（Mobile Studio） モバイルプッシュ 標準統合（MobilePush） クラウドページ ❌ カスタム統合が必要 | J28: Salesforce.Data-Cloud-Consultant.v2024-12-02.q93 | K28: 46 | M28: *
B29: 207 | C29: ◯ | D29: 01_Data Cloud の概要 | E29: 顧客が個人データの削除を要求します。 Data Cloud でこのリクエストに対応するためにコンサルタントはどのようなアクションを取る必要がありますか? A. ストリーミング API 呼び出しを使用して顧客の情報を削除します。 B. プロファイル エクスプローラーを使用して、Data Cloud から顧客データを削除します。 C. Consent API を使用して顧客情報の削除をリクエストします。 D. データ権利主体要求ツールを使用して、顧客情報の削除を要求します。 | F29: D | G29: データ権利主体リクエスト ツールは、データ クラウド ユーザーがデータへのアクセス、削除、または移植性に関する顧客のリクエストを管理できるようにする機能です。このツールは、データ権利リクエストを作成、追跡、および実行するためのユーザー インターフェイスと API を提供します。また、このツールは、顧客の個人データとリクエストに準拠するために実行されたアクションを含むレポートも生成します。コンサルタントは、このツールを使用して、データ クラウドでのデータ削除に関する顧客のリクエストに対応する必要があります。参照: データ権利主体リクエスト ツール、データ権利主体リクエストの作成 | H29: D | I29: ◾ 背景： Salesforce Data Cloud は、GDPRやCCPAなどのデータプライバシー規制に対応しており、 顧客（データ主体）からの**個人情報の削除リクエスト（Data Deletion Request）**に対処する機能を提供しています。 その代表的な機能が 「データ権利主体要求ツール（Data Subject Rights (DSR) Request Tool）」 です。 ✅ 正解理由： ▶ データ権利主体要求ツールとは？ Salesforce Data Cloud が提供する標準機能であり、GUIベースで個人データの削除を管理できる。 主に以下の2種類のリクエストに対応： Access（顧客がどの情報を持っているか開示要求） Delete（顧客データの削除要求） 削除対象の個人（Individual）は、**識別名（例：メールアドレス、CRM IDなど）**に基づいて特定される。 → この機能により、完全かつ準拠した方法でData Cloudから個人データを削除できる。 ❌ 他の選択肢の誤り： 選択肢 評価 理由 A. ストリーミング API 呼び出しで削除 ❌ ストリーミング API は**データ取り込み用途（イベント処理）**であり、削除処理には対応していない。 B. プロファイル エクスプローラーで削除 ❌ プロファイル エクスプローラーは可視化・分析用UIであり、削除操作はできない。 C. Consent API で削除リクエスト ❌ Consent API は同意ステータス（例：メール許諾）の管理用であり、データ削除のためのAPIではない。 📝 補足： DSRツールはData Cloud 管理者権限を持つユーザーのみが実行できます。 実行後、Data Cloudは該当個人のデータを完全に削除し、すべてのセグメント・アクティベーションから除外されます。 | J29: Salesforce.Data-Cloud-Consultant.v2024-12-02.q93 | K29: - | M29: *
B30: 219 | C30: ◯ | D30: 01_Data Cloud の概要 | E30: 顧客にとって Data Cloud の主な価値は何ですか? A. 顧客と関連データの統合ビューを提供する B. すべてのシステムをゴールデンレコードで接続する C. すべての匿名データのための唯一の真実のソースを作成する D. 顧客の行動に耳を傾け、理解し、行動することでパーソナライズされたキャンペーンを作成する | F30: A | G30: Data Cloud は、Salesforce アプリケーションやその他のシステム全体ですべての顧客データをアクティブ化できるプラットフォームです。Data Cloud を使用すると、CRM、マーケティング、コマース、サービス、外部データ プロバイダーなどのさまざまなソースからデータを取り込んで変換し、リンクすることで、各顧客の統合プロファイルを作成できます。また、Data Cloud は、顧客の行動、好み、ニーズに関する洞察と分析、および顧客とのやり取りをセグメント化、ターゲット設定、パーソナライズするためのツールも提供します。Data Cloud が顧客に提供する主な価値は、顧客とその関連データの統合ビューを提供することです。これにより、顧客エクスペリエンスを向上させ、ロイヤルティを高め、成長を促進することができます。参考資料: Salesforce Data Cloud、データが競争上の優位性を生み出すとき | H30: A | I30: ◾ 解説： Salesforce Data Cloud の主な価値は、 さまざまなソースから分断された顧客データを統合し、1人の顧客に関する包括的で信頼できるビュー（Customer 360）を提供することです。 この「統合ビュー」があることで、企業は顧客の行動・属性・関係性を正確に把握し、 マーケティング、営業、サービスなどの全チャネルで一貫したパーソナライズ対応ができるようになります。 ✅ A が正解である理由： Data Cloud は CRM、Web 行動、店舗データ、サービス履歴などを統一されたプロファイルに集約。 これにより、一人の顧客に関する全データが一か所で把握可能となります（＝統合ビュー）。 ❌ 他の選択肢の誤り： 選択肢 誤りの理由 B. ゴールデンレコードで接続する ❌ ゴールデンレコードは MDM（マスターデータ管理）での概念であり、Data Cloud はそこまで厳密な“正”の定義は行わない。 C. 匿名データの唯一の真実のソース ❌ Data Cloud は**主に識別可能なデータ（ファーストパーティデータ）**の統合が目的であり、匿名データ特化ではない。 D. パーソナライズされたキャンペーンの作成 ❌ パーソナライズは重要なユースケースだが、「主な価値」は統合ビューの提供にある（パーソナライズはその活用結果）。 📝 一言でまとめると： 「Data Cloud = 顧客データの統合基盤」 | J30: Salesforce.Data-Cloud-Consultant.v2024-12-02.q93 | K30: 73 | M30: *
B31: 222 | C31: ◯ | D31: 01_Data Cloud の概要 | E31: 検出中に、複数のデータ ソースを持ち、個人に関するデータを 1 つの統合プロファイルに一致させて調整する必要がある顧客に対して、コンサルタントはどの機能を強調する必要がありますか? A. データクレンジング B. 調和 C. データ統合 D. アイデンティティ解決 | F31: D | G31: アイデンティティ解決は、データ クラウドが複数のデータ ソースから個人に関するデータを 1 つの統合プロファイルに一致させて調整できるようにする機能です。アイデンティティ解決では、ルール セットを使用して、名前、電子メール、電話、または当事者 ID などの共通属性に基づいてソース プロファイルを一致させて統合する方法を定義します。アイデンティティ解決により、データ クラウドはさまざまなデータ ソースとシステムにわたって各顧客の 360 度ビューを作成できます12。他のオプションは、次の理由により、この顧客のニーズに最も適した機能ではありません。 * A. データ クレンジングは、重複、欠損値、無効な形式など、データ内のエラーや不整合を検出して修正するプロセスです。データ クレンジングにより、データの品質と精度は向上しますが、異なるデータ ソース間でのデータの一致や調整は行われません3。 * B. 調和とは、さまざまなソースからのデータを標準化し、共通の形式と構造に変換するプロセスです。調和により、データの統合と相互運用性が可能になりますが、異なるデータソース間でのデータの一致や調整は行われません4。 * C. データ統合とは、さまざまなソースからのデータを 1 つのデータ セットまたはシステムに結合するプロセスです。データ統合により、データの冗長性と複雑さを軽減できますが、さまざまなデータ ソース間でデータを一致させたり調整したりすることはできません5。参考文献: 1: Data and Identity in Data Cloud | Salesforce Trailhead、2: Data Cloud Identiy Resolution | Salesforce AI Research、3: [データ クレンジング - Salesforce]、4: [Harmonization - Salesforce]、5: [Data Consolidation - Salesforce] | H31: D | I31: ◾ 背景： 検出（Discovery）フェーズにおいて、顧客は以下のような要望を持っていると仮定されます： 複数のデータソース（例：CRM、ECサイト、モバイルアプリ）から集めた人物データを統合して、一人の顧客プロファイルにまとめたい 同一人物を見つけ出し、重複や分断されたデータをマージ（統合）したい このような課題に対して最も重要なのが、Salesforce Data Cloud におけるアイデンティティ解決機能です。 ✅ 正解理由： ▶ アイデンティティ解決（Identity Resolution）とは？ 複数のソースから取り込まれた同一人物と思われるデータをマッチング・統合する機能 以下の処理を担います： マッチング（Match）：氏名、メール、電話、ID などのルールで同一人物を特定 リンク（Link）：一致した複数のレコードを関連づけ 調整（Reconcile）：どの属性値を統合プロファイルに反映するか決定 結果として、「**Unified Individual（統合された個体）」**が生成されます。 ❌ 他の選択肢の誤り： 選択肢 評価 理由 A. データクレンジング ❌ フィールドの欠損や異常値などを整える処理であり、同一人物の統合とは直接関係しない。 B. 調和（Harmonization） ❌ 異なるデータ構造・命名を標準化する処理であり、「同一人物かどうか」の識別には使わない。 C. データ統合 ❌ 一般的な用語だが、Data Cloud の具体機能としては Identity Resolution を指すのが正確。曖昧すぎる。 📝 補足： フェーズ 対応機能 目的 前処理 データクレンジング データの整形・欠損補完 モデリング 調和（Harmonization） スキーマ標準化 統合処理 アイデンティティ解決 同一人物を見つけて統合 | J31: Salesforce.Data-Cloud-Consultant.v2024-12-02.q93 | K31: - | M31: *
B32: 225 | C32: ◯ | D32: 01_Data Cloud の概要 | E32: ある企業は、Salesforce で複数のリードと連絡先が同じメール アドレスを共有するという課題に対処する方法についてコンサルタントにアドバイスを求めています。コンサルタントは、この問題を効果的に解決するために Data Cloud を活用する方法について詳細かつ包括的な説明を提供したいと考えています。 この会社のビジネス上の課題に対処するためにコンサルタントは何を強調すべきでしょうか? A. データバンドル B. 計算された洞察 C. アイデンティティ解決 D. アイデンティティ解決 | F32: C | G32: 問題の概要: Salesforce で複数のリードと連絡先が同じメール アドレスを共有すると、データの重複、不正確な顧客ビュー、非効率的なマーケティングおよび販売活動につながる可能性があります。 Data Cloud Identity Resolution: Salesforce Data Cloud は、この問題に対処するための強力なツールとして Identity Resolution を提供します。これは、複数のソースからのデータをマージして統合し、単一の包括的な顧客プロファイルを作成するのに役立ちます。 プロセス： * データ取り込み: リードと連絡先のデータを Salesforce Data Cloud にインポートします。 * ID 解決ルール: 電子メール アドレスなどの主要な識別子に基づいてレコードを照合およびマージするための ID 解決ルールを構成します。 * 統合: このツールは、同じ電子メール アドレスを共有するレコードを統合し、重複を排除して各顧客の単一のビューを保証します。 | H32: C | I32: ◾ 背景（ビジネス課題）： この企業は、Salesforce CRM において： 複数のリード（Leads）や連絡先（Contacts）が同じメールアドレスを持っている これにより、**「誰が誰かがわからない」「重複顧客が存在している」**という状態に悩まされています。 たとえば： lead1@example.com → 見込み客のAさん contact1@example.com → すでに取引中のBさん この2人が同じメールアドレスを使っていた場合、誤って同一人物とみなしたり、逆に別人として扱ってしまう混乱が生じます。 ✅ 正解理由： ▶ アイデンティティ解決（Identity Resolution）とは？ Salesforce Data Cloud の機能であり、複数のデータソースから来た「人物レコード」を分析し、同一人物を特定・統合する機能です。 このプロセスには以下が含まれます： マッチルール（Matching Rules）： 例）メールアドレスが一致、名前＋電話番号が一致など → 同一人物かどうかを判断 リンク（Link）： 同一と判断されたレコードを紐付け 調整（Reconciliation）： 複数のソースから来た異なる属性のうち、どの値を統合後プロファイルに使うか決定 これにより、同じメールアドレスを使う複数のリード・連絡先を、1つの「統合プロファイル（Unified Individual）」として管理可能になります。 ❌ 他の選択肢の誤り： 選択肢 理由 A. データバンドル ❌ データバンドルは主に B2C Commerce などの eコマースデータ取り込みに関するパッケージであり、アイデンティティの重複解決には直接関係しない。 B. 計算された洞察（Calculated Insights） ❌ 集計・分析向けの機能であり、重複人物の統合には使われない。アイデンティティの統合処理には適していない。 D. アイデンティティ解決（重複） ⚠️ 選択肢としては正しいが、Cと内容が重複しており、形式ミス。意味としてはCが正答。 📝 コンサルタントが強調すべきポイント： 重複したリードや連絡先を1つの統合プロファイルにまとめることができる メールアドレスだけではなく、複数の条件（名前、電話番号、IDなど）で精密なマッチングができる 誤マッチを避けるための厳密なルール設計や、データソースごとの信頼度設定も可能 統合後も元データは保持され、信頼性の高い代表値を構成できる（調整ルール） | J32: Salesforce.Data-Cloud-Consultant.v2024-12-02.q93 | K32: - | M32: *
B33: 11 | C33: ◯ | D33: 02_Data Cloud の設定と管理 | E33: コンサルタントは、複数のブランドを扱う組織向けに Data Cloud を設定しており、データ スペースを使用してさまざまなブランドのデータを分離しています。 データ ストリームのマッピングを開始しているときに、コンサルタントは、ブランドの 1 つに対してオブジェクトをマッピングできないことに気付きました。 オブジェクトを新しいデータ スペースで使用できるようにするために、コンサルタントは何をする必要がありますか? A. 異なるデータ スペース間でデータを分割するバッチ変換を作成します。 B. データ コピー機能を使用して、デフォルトのデータ スペースから新しい DMO にデータをコピーし、この DMO を新しいデータ スペースにリンクします。 C. [データ スペース] タブに移動し、新しいデータ スペースに含めるオブジェクトを選択します。 D. 新しいデータ ストリームを作成し、2 番目のデータ ストリームをデータ スペースにマップします。 | F33: C | G33: - | H33: C | I33: ◾ 問題の状況： コンサルタントは、**複数ブランドを分離管理するために Data Cloud の「データスペース（Data Space）」**を使用している。 あるブランド（≒データスペース）において、特定のオブジェクト（DMO）をデータストリームにマッピングできない。 → これは、その DMO がそのデータスペースで有効になっていないことが原因です。 ■ 正解の根拠： ▶ データスペースとDMOの関係性 Data Cloud では、データスペースごとに使用できるDMO（データモデルオブジェクト）を明示的に有効化する必要があります。 つまり、「どのDMOをどのデータスペースで利用可能にするか」は、[データスペース]タブで設定します。 この操作を行わない限り、データストリームのマッピング画面に該当DMOが表示されず、マッピングができません。 | J33: Salesforce.Data-Cloud-Consultant-JPN.v2025-03-28.q66 | K33: - | M33: *
B34: 14 | C34: ◯ | D34: 02_Data Cloud の設定と管理 | E34: Northern Trail Outfitters のマーケティング マネージャーは、データ クラウド セグメント インテリジェンスからの分析情報を活用して、マーケティングの投資収益率 (ROI) を向上したいと考えています。 これを設定するには、ユーザーはどの権限セットが必要ですか? A. データクラウドユーザー B. データクラウド管理者 C. データクラウド データアウェア スペシャリスト D. クラウドマーケティングマネージャー | F34: B D | G34: 提供されたソースによると、Northern Trail Outfitters のマーケティング マネージャーが、データ クラウド セグメント インテリジェンスからの分析情報を活用してマーケティングの投資収益率 (ROI) を向上したいと考えている場合、セグメント、アクティベーション、アクティベーションターゲットへのフルアクセスを許可する「マーケティング・マネージャーのためのデータ・クラウド」権限セットが最も適しています。提供された選択肢の中で、この権限セットに最も近い名前は D です。 D. クラウドマーケティングマネージャー ただし、この権限セット名「クラウドマーケティングマネージャー」は、提供されたソース中の権限セット名（「マーケティング・マネージャーのためのデータ・クラウド」）と厳密には一致しません。 （注：選択肢C「データクラウド データアウェア スペシャリスト」およびD「クラウドマーケティングマネージャー」という名前の権限セットは、提供されたソース中には直接確認できませんでした。） | H34: A D | I34: ◾ 問題の要点： Northern Trail Outfitters のマーケティングマネージャーが、セグメントインテリジェンス（＝Data Cloudの可視化/分析機能）を活用して、マーケティングのROIを向上させたい。 この要件において重要なのは： セグメントインテリジェンス（Segment Intelligence）にアクセスして、 セグメントのパフォーマンスや指標を確認する よって必要なのは「分析と参照を行うためのユーザー権限」 ◾ 正解の根拠： ✅ 「データクラウドユーザー（Data Cloud User）」権限セットは： Data Cloud 内での セグメントの作成・閲覧・インサイト参照 などが可能 セグメントインテリジェンスを表示して ROI分析の土台となるデータの確認が可能 ■ 他の選択肢の誤り： 選択肢 評価 理由 A. データクラウドユーザー ✅ 正解 分析・セグメントの参照に必要な基本的ユーザー権限 B. データクラウド管理者 ❌ 不正解 管理目的での構成権限。セグメントインテリジェンスの閲覧には過剰 C. データクラウド データアウェア スペシャリスト ❌ 不正解 データ連携や統合に関する技術系ロールで、閲覧主体のマーケティング職には不要 D. クラウドマーケティングマネージャー ❌ 不正解 存在しないか、少なくとも Data Cloud 標準の権限セットには存在しない 名前 | J34: Salesforce.Data-Cloud-Consultant-JPN.v2025-03-28.q66 | K34: - | M34: *
B35: 17 | C35: ◯ | D35: 02_Data Cloud の設定と管理 | E35: Data Cloud の新規ユーザーは、取り込まれたデータの個々の行を確認し、リンクされたデータ モデル オブジェクトに正常にモデル化されていることを検証することのみが必要です。必要に応じて、ユーザーも変更を加える必要があります。 このユースケースに対応するために必要な最小限の権限セットは何ですか? A. マーケティング スペシャリスト向けのデータ クラウド B. データ クラウド管理者 C. データクラウドユーザー D. マーケティング データ認識スペシャリスト向けデータ クラウド | F35: C B | G35: データ クラウド ユーザー パーミッション セットは、このユースケースに対応するために必要な最小限のパーミッション セットです。データ クラウド ユーザー パーミッション セットは、データ エクスプローラー 機能へのアクセスを許可します。この機能により、ユーザーは取り込まれたデータの個々の行を確認し、そのデータが関連付けられたデータ モデル オブジェクトに正しくマッピングされていることを検証できます。ユーザーはまた、データ モデル オブジェクトのフィールドに対して変更を加えることもできます。例えば、フィールドの追加や削除、フィールド タイプの変更、または数式フィールドの作成などが可能です。データクラウド ユーザー パーミッション セットは、データ ストリームの作成、セグメントの作成、アクティベーションの作成、またはユーザーの管理など、他のデータクラウド機能やタスクへのアクセスを許可しません。他のパーミッション セットは、このユースケースには制限が厳しすぎたり、許可が広すぎたりします。データクラウド マーケティング スペシャリスト パーミッション セットはセグメンテーションとアクティベーション機能へのアクセスを許可しますが、データ エクスプローラー機能へのアクセスは許可しません。Data Cloud Admin 権限セットは、Data Explorer 機能を含むすべての Data Cloud 機能とタスクへのアクセスを許可しますが、ユーザーが必要とする範囲を超えています。Data Cloud for Marketing Data Aware Specialist 権限セットは、Data Explorer 機能へのアクセスを許可しますが、このユースケースでは不要なセグメンテーションとアクティベーション機能へのアクセスも含まれます。参照： Data Cloud 標準権限セット、Data Explorer、Data Cloud ユニットの設定 データクラウドにおいて、取り込まれたデータの個々の行を確認し、リンクされたデータ モデル オブジェクトに正常にモデル化されていることを検証し、必要に応じて変更を加えるというユースケースに対応するために必要な最小限の権限セットについて、ソースに基づき説明します。 提供されたソースでは、いくつかのData Cloudに関連する権限セットについて説明されています。 • Data Cloud管理者: Data Cloud内のすべてのナビゲーションコンポーネントへのフルアクセスを許可します。ユーザーは、データをデータモデルにマッピングし、データストリーム、ID解決ルールセット、計算されたインサイトを作成するなど、Data Cloud内のすべての機能を使用できます。 • Data Cloudユーザー: Data Cloud内のすべてのナビゲーションコンポーネントへの表示のみのアクセスを許可します。この権限セットを持つユーザーは、Data Cloud機能を表示できます。データモデルへのマッピング、データストリーム、ID解決ルールセット、計算されたインサイトを作成することはできます。しかし、「表示のみ」であるため、既存のデータやモデルに「変更を加える」という操作は制限されると解釈できます。 • マーケティング スペシャリスト向けのデータ クラウド: データエクスプローラーおよびプロファイルエクスプローラーにはアクセスできません。他のすべてのナビゲーションコンポーネントは表示のみが可能です。ユーザーはセグメントを作成できます。取り込まれたデータの個々の行を確認するためにはデータエクスプローラーが必要であると考えられるため、この権限セットでは不十分です。 • マーケティング データ認識スペシャリスト向けデータ クラウド: この名称の権限セットはソースに直接見当たりません。「マーケティング活用スペシャリスト向けデータ・クラウド」、「マーケティング・マネージャー向けデータ・クラウド」、「マーケティング・スペシャリスト向けデータ・クラウド」などのマーケティング関連の権限セットが説明されていますが、これらの権限セットの多くは表示が中心であったり、データエクスプローラーへのアクセスが制限されていたりします。 ユースケースとして「取り込まれたデータの個々の行を確認」[User Query]し、「リンクされたデータ モデル オブジェクトに正常にモデル化されていることを検証」[User Query]し、必要に応じて「変更を加える」[User Query]必要がある点を考慮すると、Data Cloud管理者の権限セットがこれらの操作をすべて可能にする最も適切な選択肢であると考えられます。Data Cloud管理者はData Cloudのすべての機能にアクセスでき、データモデルのマッピングやデータストリームの設定など、モデル化の検証や変更に関連する操作を行うことができます。 したがって、提供されたソースに基づくと、ユースケースに対応するために必要な権限セットは以下の通りです。 B. データ クラウド管理者 | H35: D B | I35: ◾ 問題の要点： 新規ユーザーが必要なのは： 取り込まれたデータの個々の行を確認 リンクされたデータモデルオブジェクト（DMO）に正常にマッピングされているかの検証 必要に応じて変更も加える つまり、データ構造と取り込み結果の確認・調整ができる中間的な役割が求められています。 ■ 正解の理由（D）： ✅ 「Data Cloud for Marketing Data Aware Specialist」 は： 取り込まれたデータの構造、行単位の確認 データストリームやマッピングの検証 一部の変更や微調整も可能 という権限を持つ、テクニカル担当者向けの準管理者的ロールです。 ■ 他の選択肢の検討： 選択肢 評価 理由 A. Data Cloud for Marketing Specialist ❌ 不正解 マーケティング担当者向けで、セグメントやアクティベーションなどの実行権限中心。データ構造の検証には不足 B. Data Cloud Admin ❌ 過剰 管理者権限であり、全構成・接続管理も含むため最小構成ではない C. Data Cloud User ❌ 不足 セグメントの作成や閲覧は可能だが、データストリームや取り込み確認・調整はできない D. Data Cloud for Marketing Data Aware Specialist ✅ 最小かつ適切 データ検証・行レベルのチェック・マッピング調整などが可能な役割 | J35: Salesforce.Data-Cloud-Consultant-JPN.v2025-03-28.q66 | K35: - | M35: *
B36: 37 | C36: ◯ | D36: 02_Data Cloud の設定と管理 | E36: Cloud Kicks のマーケティング マネージャーは、自社のアカウントの企業電話番号を Data Cloud に取り込むことを計画しています。これらの電話番号を保存するために、データが Phone に設定されたカスタム フィールドを使用する予定です。 電話番号を取り込む際に正しい記述はどれですか? A. 電話番号フィールドを主キーとして使用する必要があります。 B. Data Cloud は、取り込み時に電話番号の形式を検証します。 C. テキスト値は、電話データ型フィールドへの取り込みに受け入れられます。 D. 電話番号フィールドは 10 桁の値のみを受け入れます。 | F36: C | G36: Data Cloud への電話番号の取り込みに関するご質問ですね。提供されたソースに基づき、各選択肢について確認します。 まず、電話番号フィールドに関する情報はスライド51 に記載されています。 • A. 電話番号フィールドを主キーとして使用する必要があります。 ソースにおいて、電話番号フィールドを主キーとして使用する必要があるという特定の記述は見当たりません。主キーはデータソースやDMOの種類によって異なり、Identity Resolution で使用される Individual ID や Party ID とは異なる概念として説明されています。したがって、この記述はソースによって直接裏付けられていません。 • B. Data Cloud は、取り込み時に電話番号の形式を検証します。 スライド51 には、「Data Cloud は、取り込み時に電話番号の形式を検証しません。」と明確に記載されています。したがって、この記述は誤りです。 • C. テキスト値は、電話データ型フィールドへの取り込みに受け入れられます。 スライド51 には、「電話番号データ型はテキスト・データ型をモデルにしています。」と記載されています。これは、電話番号フィールドが内部的にはテキストとして扱われることを示唆しています。スライド50 では、テキストデータ型は「あらゆる種類のテキストデータを格納」し、「空の文字列としての文字列」も扱えることが述べられています。このことから、電話番号フィールドにはテキスト値が受け入れられると考えられます。 • D. 電話番号フィールドは 10 桁の値のみを受け入れます。 ソースには、電話番号フィールドが受け入れる桁数に関する具体的な制限（例えば「10桁のみ」）についての記述はありません。Data Cloud が形式を検証しない と記載されていることから、特定の桁数に限定されるわけではないと考えられます。したがって、この記述はソースによって直接裏付けられていません。 提供されたソースの情報に基づくと、最も正しい記述は C. テキスト値は、電話データ型フィールドへの取り込みに受け入れられます。 となります。これは、電話番号データ型がテキストデータ型をモデルにしているという記述 によって裏付けられています。 | H36: C | I36: ◾ 問題の背景： Cloud Kicks のマーケティングマネージャーは、企業の電話番号を Data Cloud に取り込もうとしている。 その際に使うフィールドは、データ型「Phone」に設定されたカスタムフィールド。 つまり、「電話番号の取り込みに関して正しい理解はどれか？」という設問です。 ✅ 正解理由（C）： Salesforce Data Cloud では、データ型「Phone」のフィールドに対しても、 「電話番号をテキスト（文字列）として」取り込むことが可能です。 取り込み時点では、文字列としての受け入れが行われる 形式（例：+81-3-1234-5678 や (800) 555-1234）については、標準化やバリデーションは行われない（後続で整形・変換が必要） ❌ 他の選択肢の誤り： 選択肢 評価 理由 A. 電話番号フィールドを主キーにする必要がある ❌ 不正解 主キー（Primary Key）にする必要は一切ない。IDやメールの方が主キーに適している B. 取り込み時に電話番号形式を検証する ❌ 不正解 Data Cloudは電話番号の形式検証を自動で行わない（+/-/() なども許容） C. テキスト値はPhone型フィールドに受け入れられる ✅ 正解 文字列として受け入れるため、形式に厳密な制限はない D. 10桁の値のみ受け入れる ❌ 不正解 国際番号や9桁番号なども受け入れ可能であり、10桁制限は存在しない | J36: Salesforce.Data-Cloud-Consultant-JPN.v2025-03-28.q66 | K36: - | M36: *
B37: 52 | C37: ◯ | D37: 02_Data Cloud の設定と管理 | E37: Northern Trail Outfitters (NTO) は、CRM データを Data Cloud に取り込み始める準備を進めています。 コネクタを設定する際に、データ ストリームが初めて展開されるときに、NTO はどのタイプの更新を予期する必要がありますか? A. 増分 B. 手動更新 C. 部分更新 D. 完全更新 | F37: D | G37: * データ ストリームの展開： Salesforce Data Cloud でデータ ストリームを設定する際、最初の展開には包括的なデータ ロードが必要です。 * リフレッシュの種類： 増分リフレッシュ： 前回のリフレッシュ以降に追加または変更されたデータのみを更新します。 手動リフレッシュ： ユーザーが手動でデータ ロードを開始する必要があります。 部分リフレッシュ： データのサブセットのみがリフレッシュされます。 フル リフレッシュ： データセット全体がシステムにロードされます。 * 初回展開： データストリームの初回展開時には、ソースシステムからのすべてのデータがSalesforce Data Cloudにインポートされるように、フルリフレッシュが必須です。 * 参照： Salesforce ドキュメント： データストリームの設定 Salesforce Data Cloud ガイド | H37: D | I37: ◾ 問題の状況： Northern Trail Outfitters（NTO）は、CRMデータをSalesforce Data Cloudに取り込むためのコネクタを初期設定しています。 → 最初に データストリームが展開されるときに起こる更新タイプは何か？ ✅ 正解理由：「最初の取り込みは常に完全更新（Full Refresh）」 Salesforce Data Cloud におけるデータストリームの動作： 初回展開時には、対象のCRMオブジェクトから すべてのデータを一括で取り込む＝完全更新（Full Refresh） が実行されます。 これは、個人・取引先・活動履歴などのフルデータセットをData Cloudに同期し、マッピング・ID解決・調和を行うために必要です。 初回以降は、設定に応じて 増分取り込み（Incremental Refresh） も可能になります。 ❌ 他の選択肢の誤り： 選択肢 評価 理由 A. 増分（Incremental） ❌ 不正解 初回取り込みでは使用されない。2回目以降に適用可能な取り込みモード B. 手動更新 ❌ 不正解 データストリームの初回取り込みは自動的にトリガーされる C. 部分更新（Partial Refresh） ❌ 不正解 Data Cloud では「部分更新」というモードは存在しない D. 完全更新（Full Refresh） ✅ 正解 初回展開時は常に全データを取得するフルリフレッシュ方式が用いられる | J37: Salesforce.Data-Cloud-Consultant-JPN.v2025-03-28.q66 | K37: - | M37: *
B38: 56 | C38: ◯ | D38: 02_Data Cloud の設定と管理 | E38: コンサルタントはトランザクション データを含むデータ ストリームを設定しています。 コンサルタントは、確実に優れたフィールド タイプを選択する必要があります。 発注書番号のゼロは保持されますか? A. テキスト B. 数値 C. 10 進数 D. シリアル | F38: A | G38: フィールドタイプ「テキスト」を選択することで、購入注文番号の先頭のゼロが保持されます。これは、テキストフィールドがアルファベットと数字を文字列として保存し、先頭や末尾の文字を削除しないためです。一方、数値、小数、シリアルフィールドは数値を数値として保存し、データを表示またはエクスポートする際、先頭のゼロを自動的に削除します123。したがって、購入注文番号、郵便番号、電話番号など、元の形式を保持する必要があるデータを格納するには、テキストフィールドが適しています。参照： フィールドの先頭にあるゼロがデータエクスポートで省略される CSVファイルをインポートする際、最初の『0』を保持する ゼロで始まるまたはプラス記号を含む住所フィールドのインポートとエクスポート | H38: A | I38: ◾ 問題の焦点： 「発注書番号（注文番号）などの先頭にゼロを含む値」をデータストリームで取り込む際、 ゼロを正確に保持したい場合に、どのフィールドタイプを選ぶべきか？ ✅ 正解理由：テキスト（Text）型ならゼロが保持される 例： 発注書番号：0012345678 のような ゼロ始まりの識別子 テキスト型であればそのまま "0012345678" として保持される 一方で、数値型や小数型にしてしまうと： 型 値の扱い 備考 数値（Number） 12345678（先頭ゼロ削除） ❌ ゼロは無視される 10進数（Decimal） 12345678.00 ❌ 同上、識別子としては不適切 シリアル（Serial） 自動連番付与 ❌ 入力された番号ではなく、独自の連番となるため不適 ✅ 発注書番号や顧客ID、SKUなどに先頭ゼロが含まれる可能性がある場合は、必ず「テキスト型」にすべきです。 ❌ 他の選択肢の誤り： 選択肢 評価 理由 A. テキスト ✅ 正解 先頭ゼロを含む識別子をそのまま扱える唯一のフィールドタイプ B. 数値 ❌ 不正解 00123 → 123 に変換されてしまい、識別子として破損 C. 10進数 ❌ 不正解 金額や量には適しているが、識別子用途には不向き（同上） D. シリアル ❌ 不正解 自動採番目的で使用され、外部から取り込んだ識別子を維持できない | J38: Salesforce.Data-Cloud-Consultant-JPN.v2025-03-28.q66 | K38: - | M38: *
